File: FSS2_60D_ScanT_0T.dat
[Header]
; ACMS Data File (default extension .dat)
; Copyright 1999, Quantum Design, Inc. All rights reserved.
TITLE,
FILEOPENTIME,9352831.33,04-19-2021,3:20 pm
BYAPP,ACMS,1.0,1.1
INFO,PPMS ACMS Option Version: 1.0.9 Build 14,APPNAME
INFO,HARMONICS,1
INFO,mcamp,11.3
INFO,tef,7
INFO,,
INFO,,
INFO,,
INFO,,
INFO,,
INFO,,
INFO,,
INFO,,
DATATYPE,COMMENT,1
DATATYPE,TIME,2
FIELDGROUP,AC Mag,2,3,4,5,6,8,9,10,11,12
FIELDGROUP,DC Mag,2,3,4,7,8
STARTUPGROUP,All
STARTUPAXIS,X,2,LINEAR,AUTO
TIMEMODE,MINUTES,RELATIVE
PLOT_APPEARANCE,ALL,HORZ_GRID_ON,VERT_GRID_ON,MARKERS_AND_LINES
RECORDS,ALL_RECORDS
DATATYPE,TIME,2
DATATYPE,COMMENT,1
[Data]
Comment,Time Stamp (sec),Temperature (K),Magnetic Field (Oe),Frequency (Hz),Amplitude (Oe),M-DC (emu),M-Std.Dev. (emu),M' (emu),M'' (emu),Moment (emu),Phase (deg),Calcoil' (emu),Calcoil'' (emu),Calcoil (emu),CC Phase (deg),Count,Gain,Measure Type,Elapsed (sec),Sample Center (cm),Max.Signal (V),PPMS Status (code),DSP Status (code),Min.Temperature (K),Max.Temperature (K),Min.Field (Oe),Max.Field (Oe),DC Position (cm),PPMS Temperature (K),PPMS Position,Bridge 1 Resistance (ohms),Bridge 1 Excitation (uA),Bridge 2 Resistance (ohms),Bridge 2 Excitation (uA),Bridge 3 Resistance (ohms),Bridge 3 Excitation (uA),Bridge 4 Resistance (ohms),Bridge 4 Excitation (uA),Signal 1 Vin (V),Signal 2 Vin (V),Digital Inputs (code),Drive 1 Iout (mA),Drive 1 Ipower (watts),Drive 2 Iout (mA),Drive 2 Ipower (watts),Pressure (),Map 20 (),Map 21 (),Map 22 (),Map 23 (),Map 24 (),Map 25 (),Map 26 (),Map 27 (),Map 28 (),Map 29 ()
,9356987.65,10.01573085,499.359,1000,10.0005122298493,,0.107731576190906,,,,,,,,,,125,1,0,0.621359593016433,0.000462031630937735,4369,0,10.0131445,10.0183172,499.359,499.359,,9.85215,,,,,,,,,,,,,,,,,,,,,,,10.01573085
,9359248.92,4.500400125,-0.504,42.1700838769804,3.99800997604517,,4.33812863044697E-7,0.00010982182012711,1.09404556191455E-5,0.000110365419154669,5.68903854638712,1.4742697721448E-8,5.41195398226786E-11,1.47427970558703E-8,0.210328350418406,1600,25,5,13.4965986394558,0.621359593016433,8.35582709495395E-5,4369,0,4.4969745,4.5038557,-0.504,-0.504,,4.51275,,,,,,,,,,,,,,,,,,,,,,,4.500400125
,9359556.20,4.5007956125,-0.504,133.349953401678,3.99793853483172,,5.17188430797031E-8,9.72500088868999E-5,1.8495961214942E-5,9.8993256385305E-5,10.7684634006586,1.47478775871688E-8,-2.34334601106499E-11,1.47478962043123E-8,-0.0910393530095348,800,25,5,13.4965986394558,0.621359593016433,0.000106166397298434,4369,0,4.4948964,4.506814,-0.504,-0.504,,4.5125375,,,,,,,,,,,,,,,,,,,,,,,4.5007956125
,9359784.81,4.5010550125,-0.504,562.339235787512,4.00078751386995,,3.51767623563364E-8,7.84904594963305E-5,2.16211375179209E-5,8.14139166206487E-5,15.4008569193402,1.47574953645318E-8,-1.51437203037246E-10,1.47582723467431E-8,-0.587932290646904,200,25,5,13.4965986394558,0.621359593016433,0.0002121967759579,4369,0,4.4986711,4.5021348,-0.504,-0.504,,4.513675,,,,,,,,,,,,,,,,,,,,,,,4.5010550125
,9359983.49,4.508774025,-0.504,5623.39981360671,4.00107201267919,,2.04921212626318E-8,3.68942636540759E-5,2.5788329746824E-5,4.50136050734374E-5,34.952755143724,1.46594026789712E-8,-1.85437548299368E-9,1.47762239877499E-8,-7.20947226708165,18,25,5,13.4965986394558,0.621359593016433,0.00105179192836995,4369,0,4.5042076,4.5125737,-0.504,-0.504,,4.5082625,,,,,,,,,,,,,,,,,,,,,,,4.508774025
,9360787.79,5.0002534875,-0.504,31.6230195712954,3.99801345046484,,4.60304910071939E-7,0.000101703910527779,7.97055455897477E-6,0.000102015759354229,4.48112179291287,1.47436086774359E-8,4.86623940606126E-11,1.47436889841708E-8,0.189108361272126,3200,25,5,13.4965986394558,0.621359593016433,8.11494738850373E-5,4369,0,4.9988146,5.0029683,-0.504,-0.504,,5.0202125,,,,,,,,,,,,,,,,,,,,,,,5.0002534875
,9361136.07,4.999520875,-0.504,100,3.99797327407436,,9.83792154998562E-8,9.1523341727832E-5,1.53481485634993E-5,9.28013348252964E-5,9.51972570636428,1.47583310722546E-8,8.90849474530053E-11,1.47585999392266E-8,0.345847338087628,800,25,5,13.4965986394558,0.621359593016433,9.71468217012247E-5,4369,0,4.9974484,5.001441,-0.504,-0.504,,5.02105,,,,,,,,,,,,,,,,,,,,,,,4.999520875
,9361376.91,5.001573575,-0.504,370,4.00158829809193,,5.63674742857521E-8,7.61317878704441E-5,1.86240900295859E-5,7.83766920313713E-5,13.7462792162672,1.47547619154471E-8,-9.46055505795424E-11,1.47550652113683E-8,-0.367367804174762,200,25,5,13.4965986394558,0.621359593016433,0.000165075299918533,4369,0,4.9997067,5.0044413,-0.504,-0.504,,5.022175,,,,,,,,,,,,,,,,,,,,,,,5.001573575
,9361578.39,5.003025775,-0.504,3162.30009319665,3.99957987663487,,1.60447635572247E-8,4.44327985966948E-5,2.4661797541012E-5,5.08180858463628E-5,29.0318463901114,1.47236579219775E-8,-1.04245526171179E-9,1.47605154237947E-8,-4.04986203605876,28,25,5,13.4965986394558,0.621359593016433,0.000692329372939849,4369,0,4.9999743,5.0056052,-0.504,-0.504,,5.01865,,,,,,,,,,,,,,,,,,,,,,,5.003025775
,9362294.49,5.499293375,-0.504,17.7830848089469,3.99801650292908,,6.276044677227E-7,9.38332329066083E-5,4.3519090838245E-6,9.3934097698225E-5,2.65542881222785,1.47892195205744E-8,6.6415539986362E-11,1.47893686495297E-8,0.257302594580525,6400,25,5,13.4965986394558,0.621359593016433,7.83059946134566E-5,4369,0,5.4972878,5.5007868,-0.504,-0.504,,5.5215625,,,,,,,,,,,,,,,,,,,,,,,5.499293375
,9362707.46,5.49963205,-0.504,74.9888164026095,3.99799281163993,,1.55351787459062E-7,8.63195309142326E-5,1.23214863236555E-5,8.71944977763917E-5,8.12367852395618,1.47497005764926E-8,7.15622591522088E-11,1.47498741775352E-8,0.277984168448997,1600,25,5,13.4965986394558,0.621359593016433,9.0886756321941E-5,4369,0,5.4978347,5.502121,-0.504,-0.504,,5.5230375,,,,,,,,,,,,,,,,,,,,,,,5.49963205
,9362961.85,5.50032555,-0.504,237.139794967381,4.00194866033216,,3.09417344881951E-8,7.38297703396528E-5,1.62590153184816E-5,7.55988794065924E-5,12.4196063959524,1.47565640683641E-8,-5.6035173965358E-11,1.47566704593026E-8,-0.217568502131087,400,25,5,13.4965986394558,0.621359593016433,0.000130726102397706,4369,0,5.4974685,5.5017447,-0.504,-0.504,,5.5240625,,,,,,,,,,,,,,,,,,,,,,,5.50032555
,9363170.26,5.5019759125,-0.504,1778.29962721342,4.00064169460917,,4.86130923226504E-8,5.02812708125822E-5,2.12980035178125E-5,5.46059625716184E-5,22.956411608843,1.47489623333403E-8,-5.79820088078431E-10,1.47603550514488E-8,-2.25128688799202,66,25,5,13.4965986394558,0.621359593016433,0.000457746659823957,4369,0,5.5000062,5.5033212,-0.504,-0.504,,5.5210625,,,,,,,,,,,,,,,,,,,,,,,5.5019759125
,9363753.10,5.9979920375,-0.504,13.3350419384902,6.00120770752217,,8.59217012948256E-7,0.000128254406710693,3.65432458999923E-6,0.000128306457081945,1.63207447388307,1.47819009530174E-8,6.95441458888596E-11,1.47820645436639E-8,0.269556443654109,6400,25,5,13.4965986394558,0.621359593016433,8.12534527561585E-5,4369,0,5.9965029,5.9996266,-0.504,-0.504,,6.017775,,,,,,,,,,,,,,,,,,,,,,,5.9979920375
,9364266.53,6.000233475,-0.504,56.2339235787512,6.00118770936224,,1.53946519153248E-7,0.000122267211605776,1.44924491407369E-5,0.000123123117715352,6.75978371359626,1.47545708092913E-8,5.83585362642092E-11,1.47546862211687E-8,0.226619969723226,1600,25,5,13.4965986394558,0.621359593016433,9.32112635341112E-5,4369,0,5.9981585,6.0024662,-0.504,-0.504,,6.0199,,,,,,,,,,,,,,,,,,,,,,,6.000233475
,9364548.33,6.00038135,-0.504,177.830382106244,6.00099700412645,,1.76793062112111E-7,0.000106982599672602,2.18535496753563E-5,0.000109191823256696,11.5450914317375,1.4756395329684E-8,-3.79200704104521E-11,1.47564440519273E-8,-0.147234820049903,400,25,5,13.4965986394558,0.621359593016433,0.00013753729990375,4369,0,5.9993649,6.0017281,-0.504,-0.504,,6.01975,,,,,,,,,,,,,,,,,,,,,,,6.00038135
,9364762.75,6.0014755125,-0.504,1000,5.99869618500726,,3.61066963972117E-8,8.0434177483129E-5,2.67618749246484E-5,8.47694217089513E-5,18.4031973401961,1.47788510657781E-8,-2.82601915146792E-10,1.47815527826712E-8,-1.09547919819693,66,25,5,13.4965986394558,0.621359593016433,0.000414413563407251,4369,0,5.9996219,6.0028191,-0.504,-0.504,,6.0191,,,,,,,,,,,,,,,,,,,,,,,6.0014755125
,9364956.10,6.020361375,-0.504,10000,6.0009597661693,,5.5610291302053E-8,3.11476505050714E-5,2.52405216514293E-5,4.00906481017998E-5,39.019604973403,1.44918433156807E-8,-3.28539483566528E-9,1.48595875418012E-8,-12.7734123934745,11,5,5,13.4965986394558,0.621359593016433,0.00227638741064859,4369,0,6.0158997,6.02423,-0.504,-0.504,,5.998825,,,,,,,,,,,,,,,,,,,,,,,6.020361375
,9365828.20,7.000502,-0.504,42.1700838769804,6.00119698287115,,2.15566557459497E-7,0.00010757507088868,9.99861484065059E-6,0.000108038734606789,5.31012671382181,1.47325395483868E-8,5.01900788888229E-11,1.4732625040664E-8,0.195191640884254,1600,25,5,13.4965986394558,0.621359593016433,8.84953625856558E-5,4369,0,6.9984617,7.0036035,-0.504,-0.504,,7.022725,,,,,,,,,,,,,,,,,,,,,,,7.000502
,9366136.39,7.00053895,-0.504,133.349953401678,6.00108974632167,,8.35735874840288E-8,9.62566121794234E-5,1.76270880952524E-5,9.78572921298035E-5,10.3773642079451,1.47543422772472E-8,-2.17321898267659E-11,1.4754358282292E-8,-0.0843929083911803,800,25,5,13.4965986394558,0.621359593016433,0.000119519321422001,4369,0,6.9990644,7.0020137,-0.504,-0.504,,7.022175,,,,,,,,,,,,,,,,,,,,,,,7.00053895
,9366362.98,7.0006934875,-0.504,562.339235787512,5.99909099519684,,4.48950473371031E-8,7.74175143971741E-5,2.09773317524815E-5,8.0209226295298E-5,15.1610238037477,1.47642317809985E-8,-1.51444699937118E-10,1.47650084856117E-8,-0.587693146243055,200,25,5,13.4965986394558,0.621359593016433,0.000271033819674393,4369,0,6.9997482,7.0015182,-0.504,-0.504,,7.021225,,,,,,,,,,,,,,,,,,,,,,,7.0006934875
,9366561.08,7.011782225,-0.504,5623.39981360671,6.00160801901878,,2.04766746167265E-8,3.75985234467883E-5,2.53296804740045E-5,4.53347733896824E-5,33.9676828197302,1.4662827533658E-8,-1.8533546416706E-9,1.47794937230475E-8,-7.20387980443104,18,25,5,13.4965986394558,0.621359593016433,0.00148623888308543,4369,0,7.0089397,7.0150285,-0.504,-0.504,,7.0129375,,,,,,,,,,,,,,,,,,,,,,,7.011782225
,9367370.20,7.99939095,-0.504,31.6230195712954,6.00120219813499,,2.01778433565431E-7,9.59408033612353E-5,6.85983736237912E-6,9.61857324047466E-5,4.08973008559274,1.47429464956523E-8,4.82234430202945E-11,1.47430253636804E-8,0.187410970096555,3200,25,5,13.4965986394558,0.621359593016433,8.5003228389564E-5,4369,0,7.9980497,8.0009108,-0.504,-0.504,,8.023575,,,,,,,,,,,,,,,,,,,,,,,7.99939095
,9367714.60,7.9998852125,-0.504,100,6.00114189152375,,6.5201064896568E-8,8.75410858107784E-5,1.38853357583342E-5,8.86354570928121E-5,9.0128904697225,1.47695626972117E-8,8.88559022387831E-11,1.47698299800042E-8,0.344695836069928,800,25,5,13.4965986394558,0.621359593016433,0.000106942088498962,4369,0,7.9989147,8.0009584,-0.504,-0.504,,8.0246625,,,,,,,,,,,,,,,,,,,,,,,7.9998852125
,9367956.15,8.000275125,-0.504,370,6.00029175314724,,3.4715610922892E-8,7.2868393427068E-5,1.75472803931174E-5,7.49513829748101E-5,13.5394901874259,1.47607647820358E-8,-9.47934827158461E-11,1.47610691602931E-8,-0.36794786053855,200,25,5,13.4965986394558,0.621359593016433,0.000203563441967571,4369,0,7.9992914,8.0012331,-0.504,-0.504,,8.024625,,,,,,,,,,,,,,,,,,,,,,,8.000275125
,9368156.60,8.006648775,-0.504,3162.30009319665,6.00143785004881,,1.94140935642101E-8,4.38714327372618E-5,2.32678894125757E-5,4.9659815627285E-5,27.9399313356147,1.47270594549004E-8,-1.04209060326434E-9,1.47638827214789E-8,-4.04751810728692,28,25,5,13.4965986394558,0.621359593016433,0.000959655493164429,4369,0,8.0045376,8.0082235,-0.504,-0.504,,8.0203,,,,,,,,,,,,,,,,,,,,,,,8.006648775
,9368879.61,8.9977385,-0.504,17.7830848089469,6.0012067800243,,7.45466469845771E-7,8.58851867047068E-5,2.80415188558704E-6,8.59309522995049E-5,1.87004324694589,1.47657572217856E-8,5.60314026572033E-11,1.47658635321744E-8,0.217418411735704,6400,25,5,13.4965986394558,0.621359593016433,8.19741269836137E-5,4369,0,8.9965534,8.9990349,-0.504,-0.504,,9.0282375,,,,,,,,,,,,,,,,,,,,,,,8.9977385
,9369291.45,8.9994001375,-0.504,74.9888164026095,6.00117121830889,,1.14015869339087E-7,8.11214234645589E-5,1.03397590512586E-5,8.17777228966078E-5,7.2637688446807,1.4757242131688E-8,7.22302862154021E-11,1.47574188985579E-8,0.280435698514708,1600,25,5,13.4965986394558,0.621359593016433,9.84715598371143E-5,4369,0,8.9985771,9.000371,-0.504,-0.504,,9.029725,,,,,,,,,,,,,,,,,,,,,,,8.9994001375
,9369546.42,9.0004808875,-0.504,237.139794967381,6.00083210823056,,6.37737138098674E-8,7.03326483594416E-5,1.49026647023513E-5,7.18941641615199E-5,11.9633611006021,1.47579882684763E-8,-5.62536193791327E-11,1.47580954801823E-8,-0.218395576986609,400,25,5,13.4965986394558,0.621359593016433,0.000155865811504652,4369,0,8.9988251,9.001545,-0.504,-0.504,,9.0308375,,,,,,,,,,,,,,,,,,,,,,,9.0004808875
,9369750.18,9.0022404375,-0.504,1778.29962721342,6.00096254191376,,2.30844773957387E-8,4.83183080445187E-5,1.96568473057519E-5,5.21636898453958E-5,22.1374680683521,1.47502950154347E-8,-5.79881178024276E-10,1.47616891046718E-8,-2.25132062509874,66,25,5,13.4965986394558,0.621359593016433,0.000623539304468526,4369,0,9.0017815,9.0026112,-0.504,-0.504,,9.0293,,,,,,,,,,,,,,,,,,,,,,,9.0022404375
,9370341.65,9.99356615,-0.504,13.3350419384902,6.00120770752217,,4.71094529234254E-7,7.79033988019215E-5,1.85238487922777E-6,7.7925418668314E-5,1.36212080116981,1.47769833335878E-8,6.43023201153959E-11,1.47771232393015E-8,0.249322085432349,6400,25,5,13.4965986394558,0.621359593016433,8.12512071654208E-5,4369,0,9.9925833,9.9946823,-0.504,-0.504,,10.0287,,,,,,,,,,,,,,,,,,,,,,,9.99356615
,9370856.01,9.9986412625,-0.504,56.2339235787512,6.00118770936224,,1.9985228257119E-7,7.46489256424872E-5,7.6304713054277E-6,7.50378983708935E-5,5.83639475032833,1.47554019141037E-8,5.84107983702549E-11,1.47555175262713E-8,0.226810137924458,1600,25,5,13.4965986394558,0.621359593016433,9.23114232456573E-5,4369,0,9.9980612,9.9994402,-0.504,-0.504,,10.0347875,,,,,,,,,,,,,,,,,,,,,,,9.9986412625
,9371133.37,9.9991500375,-0.504,177.830382106244,6.00099700412645,,1.06957727604738E-7,6.6441390521058E-5,1.28028923804206E-5,6.76636714025803E-5,10.9068991241656,1.47579146629974E-8,-3.74517384614569E-11,1.47579621842932E-8,-0.145401433185327,400,25,5,13.4965986394558,0.621359593016433,0.000134095130101572,4369,0,9.9982815,10.0002012,-0.504,-0.504,,10.0357,,,,,,,,,,,,,,,,,,,,,,,9.9991500375
,9371346.54,10.000638875,-0.504,1000,5.99869618500726,,2.86058006471481E-8,5.04403466713522E-5,1.59215779266614E-5,5.28935271654382E-5,17.5183866983953,1.47801575351362E-8,-2.82684527294869E-10,1.47828605927748E-8,-1.0957025202971,66,25,5,13.4965986394558,0.621359593016433,0.000398482506693393,4369,0,10.0000525,10.001195,-0.504,-0.504,,10.035525,,,,,,,,,,,,,,,,,,,,,,,10.000638875
,9371541.24,10.015342975,-0.504,10000,6.0009597661693,,2.76023723413128E-8,2.09240205197828E-5,1.60586036448282E-5,2.63760001845234E-5,37.5052356251474,1.44955992063811E-8,-3.28925393972703E-9,1.48641040036743E-8,-12.784718774999,11,5,5,13.4965986394558,0.621359593016433,0.0022089613614862,4369,0,10.011528,10.0171967,-0.504,-0.504,,10.0229,,,,,,,,,,,,,,,,,,,,,,,10.015342975
,9372603.38,11.0023628375,-0.504,42.1700838769804,6.00119698287115,,2.96234004191213E-7,6.96179357889775E-5,5.22265445871318E-6,6.98135595934866E-5,4.2902248371262,1.47327759044122E-8,4.74683723166716E-11,1.4732852374744E-8,0.18460390632427,1600,25,5,13.4965986394558,0.621359593016433,8.80627655699766E-5,4369,0,10.9997425,11.0073967,-0.504,-0.504,,10.9937375,,,,,,,,,,,,,,,,,,,,,,,11.0023628375
,9372918.73,11.0045956375,-0.504,133.349953401678,6.00108974632167,,6.73163129499024E-8,6.3406399195983E-5,1.07003437232978E-5,6.43029456152444E-5,9.57887439945612,1.47529431527997E-8,-2.3027454739746E-11,1.47529611242425E-8,-0.0894313008853942,800,25,5,13.4965986394558,0.621359593016433,0.000117709375287436,4369,0,11.0027008,11.010972,-0.504,-0.504,,10.991575,,,,,,,,,,,,,,,,,,,,,,,11.0045956375
,9373145.49,11.0075261625,-0.504,562.339235787512,5.99909099519684,,2.07717636280615E-8,5.13908821165558E-5,1.32939224221461E-5,5.30824937063414E-5,14.5034867524862,1.4762723702309E-8,-1.51471225541678E-10,1.47635007583866E-8,-0.587856115531338,200,25,5,13.4965986394558,0.621359593016433,0.000263486068406391,4369,0,11.0037727,11.018487,-0.504,-0.504,,10.9888,,,,,,,,,,,,,,,,,,,,,,,11.0075261625
,9373347.43,11.0156131875,-0.504,5623.39981360671,6.00160801901878,,2.22343740668336E-8,2.62747047182931E-5,1.68267821998397E-5,3.12009728571776E-5,32.636212213946,1.46597528434989E-8,-1.85263779542384E-9,1.47763534146117E-8,-7.20261720179207,18,25,5,13.4965986394558,0.621359593016433,0.00144657390891266,4369,0,11.0086718,11.031086,-0.504,-0.504,,10.9813625,,,,,,,,,,,,,,,,,,,,,,,11.0156131875
,9374167.70,12.0072082125,-0.504,31.6230195712954,6.00120219813499,,1.96837117985894E-7,6.50588460059815E-5,3.71619120501548E-6,6.51648948491613E-5,3.26920883120524,1.47402305142529E-8,4.6770484199769E-11,1.47403047150153E-8,0.181797859593437,3200,25,5,13.4965986394558,0.621359593016433,8.5683882982087E-5,4369,0,12.0017557,12.0369282,-0.504,-0.504,,11.9765375,,,,,,,,,,,,,,,,,,,,,,,12.0072082125
,9374521.56,12.007619275,-0.504,100,6.00114189152375,,4.6404133924752E-8,6.02687551213613E-5,8.50167623158218E-6,6.08654363545129E-5,8.0293221280391,1.47662272823021E-8,8.77574105688127E-11,1.47664880562615E-8,0.340511489685971,800,25,5,13.4965986394558,0.621359593016433,0.000106257824921325,4369,0,12.0008421,12.0302095,-0.504,-0.504,,11.9731875,,,,,,,,,,,,,,,,,,,,,,,12.007619275
,9374770.96,12.0069297625,-0.504,370,6.00029175314724,,3.12437735189333E-8,5.07094284665005E-5,1.15932455349591E-5,5.20177803970237E-5,12.8777064237337,1.4756890840442E-8,-9.561434934958E-11,1.47572005943038E-8,-0.371231452319876,200,25,5,13.4965986394558,0.621359593016433,0.000199813947033007,4369,0,11.9999142,12.0310431,-0.504,-0.504,,11.9733375,,,,,,,,,,,,,,,,,,,,,,,12.0069297625
,9374978.30,12.0085760375,-0.504,3162.30009319665,6.00143785004881,,1.73224045300295E-8,3.17619523682075E-5,1.58446504628491E-5,3.54947118107775E-5,26.5126044636629,1.47233224985596E-8,-1.03983912093302E-9,1.47599963006098E-8,-4.03982394083408,28,25,5,13.4965986394558,0.621359593016433,0.000938088656406271,4369,0,11.9996805,12.0323296,-0.504,-0.504,,11.9688,,,,,,,,,,,,,,,,,,,,,,,12.0085760375
,9375771.54,14.0121023625,-0.504,17.7830848089469,8.00021503148884,,2.55123032193374E-7,7.54711438756749E-5,2.29560857895014E-6,7.55060486097012E-5,1.74223067865891,1.47403634754827E-8,4.8451201597315E-11,1.47404431042042E-8,0.188329098592394,6400,25,5,13.4965986394558,0.621359593016433,8.62630448932341E-5,4369,0,13.9974804,14.0572472,-0.504,-0.504,,13.9734125,,,,,,,,,,,,,,,,,,,,,,,14.0121023625
,9376193.30,14.0119948375,-0.504,74.9888164026095,8.00016762412886,,1.08229535456019E-7,7.16796639367102E-5,7.69674009456497E-6,7.209170569603E-5,6.12876070541085,1.47599774971768E-8,7.12473398036208E-11,1.47601494538705E-8,0.276568183651233,1600,25,5,13.4965986394558,0.621359593016433,0.000106769017612823,4369,0,14.0018797,14.0519514,-0.504,-0.504,,13.968225,,,,,,,,,,,,,,,,,,,,,,,14.0119948375
,9376457.49,14.0089488,-0.504,237.139794967381,7.99971555612896,,3.23061063622399E-8,6.32887071318141E-5,1.24421119014197E-5,6.45001286741662E-5,11.1221070466541,1.47536510476619E-8,-5.65610515117891E-11,1.47537594662759E-8,-0.219653674173117,400,25,5,13.4965986394558,0.621359593016433,0.000181140256055858,4369,0,13.9986753,14.0488939,-0.504,-0.504,,13.9693125,,,,,,,,,,,,,,,,,,,,,,,14.0089488
,9376672.43,14.0085586375,-0.504,1778.29962721342,8.00128338921835,,5.80231128744386E-8,4.52615915716605E-5,1.66779874969128E-5,4.8236572624379E-5,20.2278289682637,1.47450284071534E-8,-5.77960958042637E-10,1.47563512291075E-8,-2.24467387313939,66,25,5,13.4965986394558,0.621359593016433,0.000793395399019364,4369,0,13.9972782,14.0518847,-0.504,-0.504,,13.9649,,,,,,,,,,,,,,,,,,,,,,,14.0085586375
,9377334.44,16.0120274,-0.504,13.3350419384902,8.00021626793723,,2.8664488794293E-7,6.66595092669792E-5,1.44875670345603E-6,6.6675250818428E-5,1.24505235078547,1.47443389000964E-8,6.41202017631549E-11,1.47444783224491E-8,0.249166395853978,6400,25,5,13.4965986394558,0.621359593016433,8.50632578419622E-5,4369,0,15.999507,16.0515537,-0.504,-0.504,,15.9771875,,,,,,,,,,,,,,,,,,,,,,,16.0120274
,9377852.97,16.012411575,-0.504,56.2339235787512,8.00018960836931,,1.02526289927806E-7,6.45081568268027E-5,5.17969225219225E-6,6.4715774808147E-5,4.59072428238571,1.47487844228547E-8,5.9212080659353E-11,1.47489032820185E-8,0.230024657875616,1600,25,5,13.4965986394558,0.621359593016433,9.87679778144874E-5,4369,0,15.9992952,16.0554504,-0.504,-0.504,,15.968025,,,,,,,,,,,,,,,,,,,,,,,16.012411575
,9378136.91,16.0099227375,-0.504,177.830382106244,7.99993537902014,,7.07245299442891E-8,5.89756560740327E-5,9.81382791430897E-6,5.97866141179969E-5,9.44771914083858,1.47507145163009E-8,-3.77105855858135E-11,1.47507627202689E-8,-0.146477832476421,400,25,5,13.4965986394558,0.621359593016433,0.000152947185143028,4369,0,15.9975643,16.0513172,-0.504,-0.504,,15.9701625,,,,,,,,,,,,,,,,,,,,,,,16.0099227375
,9378359.38,16.006343975,-0.504,1000,7.99965403502013,,1.3626684029667E-8,4.58497093433692E-5,1.25764344397663E-5,4.75432702923261E-5,15.3387937024742,1.47751749517016E-8,-2.82409594617417E-10,1.47778736641143E-8,-1.09500617483633,66,25,5,13.4965986394558,0.621359593016433,0.000498311166448066,4369,0,15.9947462,16.0518723,-0.504,-0.504,,15.962225,,,,,,,,,,,,,,,,,,,,,,,16.006343975
,9378560.26,16.0186166625,-0.504,10000,8.00002004091965,,6.01458510991922E-8,2.09047760233345E-5,1.5151937317195E-5,2.5818421040993E-5,35.9348797238056,1.44925976349416E-8,-3.27811908351171E-9,1.48587163286065E-8,-12.7454080328517,11,5,5,13.4965986394558,0.621359593016433,0.00290736924441912,4369,0,16.0055866,16.0560951,-0.504,-0.504,,15.9514625,,,,,,,,,,,,,,,,,,,,,,,16.0186166625
,9379501.05,18.01175285,-0.504,42.1700838769804,8.00010931193236,,1.31176404897706E-7,5.7828741312094E-5,3.053964178161E-6,5.79093258374036E-5,3.0230099522721,1.47514074817451E-8,4.90205978783133E-11,1.47514889320198E-8,0.19039966405757,1600,25,5,13.4965986394558,0.621359593016433,9.35938159562079E-5,4369,0,18.0008488,18.0485153,-0.504,-0.504,,17.9685,,,,,,,,,,,,,,,,,,,,,,,18.01175285
,9379813.79,18.0114288375,-0.504,133.349953401678,7.99996793470053,,5.53862009567387E-8,5.46787449124626E-5,7.32739178109915E-6,5.51675250080686E-5,7.63262296015686,1.47536989032751E-8,-2.41006343073215E-11,1.47537185878366E-8,-0.0935943867505671,800,25,5,13.4965986394558,0.621359593016433,0.000131791474803394,4369,0,17.9996662,18.0588112,-0.504,-0.504,,17.9714625,,,,,,,,,,,,,,,,,,,,,,,18.0114288375
,9380044.85,18.005629525,-0.504,562.339235787512,8.00148364600074,,3.43827456376351E-8,4.53005901150298E-5,1.01770814483085E-5,4.64296936407666E-5,12.661660707856,1.4760809151482E-8,-1.51679261129171E-10,1.47615884444978E-8,-0.588739786993813,200,25,5,13.4965986394558,0.621359593016433,0.000322098553049117,4369,0,17.9947948,18.0437756,-0.504,-0.504,,17.9645625,,,,,,,,,,,,,,,,,,,,,,,18.005629525
,9380246.88,18.0118019625,-0.504,5623.39981360671,7.99801630575053,,2.47468743579724E-8,2.65906885362105E-5,1.47895393159842E-5,3.04268826863482E-5,29.0824800077734,1.46534353919112E-8,-1.83290934681921E-9,1.47676242320345E-8,-7.12975138366352,18,5,5,13.4965986394558,0.621359593016433,0.00191759191278455,4369,0,18.0011292,18.0482616,-0.504,-0.504,,17.9566,,,,,,,,,,,,,,,,,,,,,,,18.0118019625
,9381133.53,20.0114870125,-0.504,31.6230195712954,7.99976103985724,,2.32498559491238E-7,5.28824274513474E-5,1.82670704313782E-6,5.29139678324019E-5,1.97836995802227,1.47346451467182E-8,4.32948693200944E-11,1.47347087533285E-8,0.168351943534999,3200,25,5,13.4965986394558,0.621359593016433,9.03407569740093E-5,4369,0,20.0005684,20.0529728,-0.504,-0.504,,19.9725375,,,,,,,,,,,,,,,,,,,,,,,20.0114870125
,9381482.77,20.0157275375,-0.504,100,7.99968404515005,,1.05439516897117E-7,5.11198330427639E-5,5.18982324629779E-6,5.13826001254108E-5,5.79696027713421,1.47664048543632E-8,8.72084467326005E-11,1.47666623729312E-8,0.338377410931947,800,25,5,13.4965986394558,0.621359593016433,0.000116953252806193,4369,0,20.0056839,20.056057,-0.504,-0.504,,19.973025,,,,,,,,,,,,,,,,,,,,,,,20.0157275375
,9381729.02,20.0078508875,-0.504,370,7.99855066793429,,3.70315763466541E-8,4.41484014736072E-5,8.66436372670362E-6,4.49905829198003E-5,11.1034887602739,1.47609488381036E-8,-9.59046658483371E-11,1.47612603901578E-8,-0.372256237110037,200,25,5,13.4965986394558,0.621359593016433,0.000239573735036923,4369,0,19.9973507,20.0453014,-0.504,-0.504,,19.9627,,,,,,,,,,,,,,,,,,,,,,,20.0078508875
,9381930.19,20.01256325,-0.504,3162.30009319665,7.99872361801706,,2.19831715716052E-8,3.13746101418984E-5,1.19693422461384E-5,3.35802220862416E-5,20.8817388900976,1.4724688736646E-8,-1.03963011491596E-9,1.47613444227466E-8,-4.03864110835781,28,25,5,13.4965986394558,0.621359593016433,0.00123910780337245,4369,0,20.0001221,20.0543652,-0.504,-0.504,,19.9546875,,,,,,,,,,,,,,,,,,,,,,,20.01256325
,9382764.67,22.01734495,-0.504,17.7830848089469,7.99913549883869,,1.97222265805032E-7,4.86201711165331E-5,1.27098108584825E-6,4.86367806533445E-5,1.49742934886829,1.47556529282458E-8,4.81743607241321E-11,1.47557315680342E-8,0.187059004220545,6400,25,5,13.4965986394558,0.621359593016433,8.68200315958467E-5,4369,0,22.0072422,22.0610657,-0.504,-0.504,,21.972625,,,,,,,,,,,,,,,,,,,,,,,22.01734495
,9383181.11,22.019253975,-0.504,74.9888164026095,7.9990912016631,,7.20534284740152E-8,4.74475258994151E-5,3.38797739971125E-6,4.75683309023621E-5,4.08425724640956,1.47727300277106E-8,6.9124860330595E-11,1.47728917520551E-8,0.268097626077275,1600,25,5,13.4965986394558,0.621359593016433,0.000106438113777692,4369,0,22.0088043,22.0590611,-0.504,-0.504,,21.9641375,,,,,,,,,,,,,,,,,,,,,,,22.019253975
,9383446.52,22.0093317,-0.504,237.139794967381,7.99864146878563,,3.6362448304223E-8,4.36063351861319E-5,6.79490870780157E-6,4.41325645381349E-5,8.85682505613959,1.47645032189755E-8,-5.95443589944527E-11,1.47646232879077E-8,-0.231069201411344,400,25,5,13.4965986394558,0.621359593016433,0.000179589515252155,4369,0,21.9971046,22.05933,-0.504,-0.504,,21.959775,,,,,,,,,,,,,,,,,,,,,,,22.0093317
,9383658.92,22.0100839,-0.504,1778.29962721342,8.00021515696927,,1.84415068986719E-8,3.32364773898226E-5,8.71504810794808E-6,3.4360085750883E-5,14.6929377808915,1.47523778416396E-8,-5.79940612660206E-10,1.47637726579866E-8,-2.25123357568441,66,25,5,13.4965986394558,0.621359593016433,0.000800452969909199,4369,0,21.9951496,22.0528202,-0.504,-0.504,,21.951775,,,,,,,,,,,,,,,,,,,,,,,22.0100839
,9384390.26,24.018075225,-0.504,13.3350419384902,7.99820324257896,,2.19664514046806E-7,4.52731645219782E-5,6.08987927822665E-7,4.52772602100695E-5,0.770662580162595,1.47709873845994E-8,5.52034719919962E-11,1.47710905399471E-8,0.214129980040659,6400,25,5,13.4965986394558,0.621359593016433,8.57370152629338E-5,4369,0,24.0091305,24.0546703,-0.504,-0.504,,23.9830125,,,,,,,,,,,,,,,,,,,,,,,24.018075225
,9384908.27,24.0175466375,-0.504,56.2339235787512,7.99818109053138,,8.60969540979206E-8,4.40772483662095E-5,2.1213933760835E-6,4.41282690958144E-5,2.75546163783091,1.47712617995792E-8,5.02893182943815E-11,1.47713474052722E-8,0.195064890157112,1600,25,5,13.4965986394558,0.621359593016433,9.91096284052908E-5,4369,0,24.010479,24.0556526,-0.504,-0.504,,23.96495,,,,,,,,,,,,,,,,,,,,,,,24.0175466375
,9385196.59,24.009248725,-0.504,177.830382106244,7.99793263643408,,5.37830116699046E-8,4.21219145564572E-5,5.08957176427696E-6,4.24282856906239E-5,6.88962351594579,1.47688242774186E-8,-4.44025778788413E-11,1.47688910256049E-8,-0.172259659863585,400,25,5,13.4965986394558,0.621359593016433,0.000152013660993509,4369,0,23.9966431,24.0503082,-0.504,-0.504,,23.9642625,,,,,,,,,,,,,,,,,,,,,,,24.009248725
,9385418.50,24.0112900625,-0.504,1000,8.00182938241406,,2.20049746863612E-8,3.36250867130342E-5,7.05806373530776E-6,3.4357862566678E-5,11.8545493549466,1.47881001129435E-8,-2.87115693837566E-10,1.47908870718455E-8,-1.11227614079053,66,25,5,13.4965986394558,0.621359593016433,0.000500974767582797,4369,0,23.999609,24.051157,-0.504,-0.504,,23.9562,,,,,,,,,,,,,,,,,,,,,,,24.0112900625
,9385636.33,24.0182704875,-0.504,10000,7.99837337544343,,4.60641649432476E-8,2.11638476522161E-5,1.09096752337076E-5,2.38102805769102E-5,27.2704888533162,1.45047431346868E-8,-3.26266465316559E-9,1.48671636179286E-8,-12.6769900301659,11,5,5,13.4965986394558,0.621359593016433,0.00303265570947173,4369,0,24.0063629,24.0579338,-0.504,-0.504,,23.9387375,,,,,,,,,,,,,,,,,,,,,,,24.0182704875
,9386638.44,26.020123475,-0.504,42.1700838769804,8.00111741559449,,1.30268029326177E-7,4.11657398577393E-5,1.59671595444956E-6,4.11966945260691E-5,2.22124631081322,1.47855380848596E-8,3.6323785934109E-11,1.47855827033046E-8,0.140758857138368,1600,25,5,13.4965986394558,0.621359593016433,9.49783830453229E-5,4369,0,26.0066528,26.0617809,-0.504,-0.504,,25.9669375,,,,,,,,,,,,,,,,,,,,,,,26.020123475
,9386954.49,26.0132455875,-0.504,133.349953401678,8.00098837188248,,5.75869200265985E-8,3.98165337169303E-5,3.43850381012134E-6,3.99647302716241E-5,4.93574297091194,1.47813409392208E-8,-3.4511093025441E-11,1.47813812269702E-8,-0.133772462995353,800,25,5,13.4965986394558,0.621359593016433,0.000131709991939484,4369,0,25.9957523,26.0735359,-0.504,-0.504,,25.9724625,,,,,,,,,,,,,,,,,,,,,,,26.0132455875
,9387188.98,26.0106265625,-0.504,562.339235787512,7.99832015372065,,4.40311638102185E-8,3.43194063300127E-5,6.23350340389789E-6,3.48809147748583E-5,10.2945216613803,1.478040981558E-8,-1.60582469342289E-10,1.47812821177987E-8,-0.622468245850769,200,25,5,13.4965986394558,0.621359593016433,0.000323698696849049,4369,0,25.9963799,26.0550919,-0.504,-0.504,,25.9547125,,,,,,,,,,,,,,,,,,,,,,,26.0106265625
,9387412.12,26.0167305375,-0.504,5623.39981360671,7.99909971514189,,3.04992931739631E-8,2.54662239627609E-5,8.19046103925343E-6,2.67509292353934E-5,17.8288580690336,1.46566022575904E-8,-1.83340495925853E-9,1.47708281244431E-8,-7.13013431344905,18,5,5,13.4965986394558,0.621359593016433,0.00202759021463319,4369,0,26.0023384,26.0701675,-0.504,-0.504,,25.952525,,,,,,,,,,,,,,,,,,,,,,,26.0167305375
,9388363.32,28.0146925375,-0.504,31.6230195712954,7.99952891706773,,2.19896328763417E-7,3.78168597988726E-5,6.86274199121354E-7,3.7823086300882E-5,1.03965003552565,1.47860843335267E-8,2.99866030800116E-11,1.4786114740341E-8,0.116197324741534,3200,25,5,13.4965986394558,0.621359593016433,9.22189530270666E-5,4369,0,27.9989395,28.0576057,-0.504,-0.504,,27.96795,,,,,,,,,,,,,,,,,,,,,,,28.0146925375
,9388719.36,28.0135273875,-0.504,100,7.99946619329184,,9.20255117507601E-8,3.76600661243992E-5,2.38237579542172E-6,3.77353454326939E-5,3.6197076907149,1.48052044804722E-8,7.42879923270778E-11,1.48053908565224E-8,0.287490302048819,800,25,5,13.4965986394558,0.621359593016433,0.000117647461142811,4369,0,27.9977398,28.0707664,-0.504,-0.504,,27.97515,,,,,,,,,,,,,,,,,,,,,,,28.0135273875
,9388967.28,28.0091679,-0.504,370,7.99832456809752,,3.44869000784737E-8,3.43438023593025E-5,5.0992956543106E-6,3.4720304962153E-5,8.44545576569074,1.47881094728331E-8,-1.09362225695983E-10,1.47885138495017E-8,-0.423710668111198,200,25,5,13.4965986394558,0.621359593016433,0.000240344935055976,4369,0,27.9951649,28.0546055,-0.504,-0.504,,27.95875,,,,,,,,,,,,,,,,,,,,,,,28.0091679
,9389177.49,28.0115189375,-0.504,3162.30009319665,7.9985479458301,,2.3665438428237E-8,2.66051316556902E-5,5.50350692424902E-6,2.71683937486534E-5,11.6872976531085,1.47356219050475E-8,-1.04522602151927E-9,1.47726453407837E-8,-4.05730445985313,28,25,5,13.4965986394558,0.621359593016433,0.00131184661192015,4369,0,27.9968605,28.0602245,-0.504,-0.504,,27.9547125,,,,,,,,,,,,,,,,,,,,,,,28.0115189375
,9390051.40,30.01570655,-0.504,17.7830848089469,8.00174891280471,,4.21902005749538E-7,3.55603677084763E-5,1.17901326825552E-7,3.55605631604015E-5,0.18996495561584,1.48123515761369E-8,4.09583818630025E-11,1.48124082040744E-8,0.158431051497197,6400,25,5,13.4965986394558,0.621359593016433,8.88703361390129E-5,4369,0,30.0021191,30.0721302,-0.504,-0.504,,29.97085,,,,,,,,,,,,,,,,,,,,,,,30.01570655
,9390473.80,30.0173516125,-0.504,74.9888164026095,8.00172177776125,,7.98185214745655E-8,3.53182559529337E-5,1.57923327840775E-6,3.53535455266451E-5,2.56023883756806,1.48224982694148E-8,5.41748044068023E-11,1.48225972709319E-8,0.209409626555145,1600,25,5,13.4965986394558,0.621359593016433,0.000108275488199126,4369,0,30.003603,30.0702839,-0.504,-0.504,,29.971075,,,,,,,,,,,,,,,,,,,,,,,30.0173516125
,9390738.92,30.0098889,-0.504,237.139794967381,8.00126346839585,,5.11740522010601E-8,3.40393396571453E-5,3.60898006966921E-6,3.42301238887296E-5,6.05210639522618,1.480445727479E-8,-7.7459979955948E-11,1.48046599167146E-8,-0.29978062360118,400,25,5,13.4965986394558,0.621359593016433,0.000179945601783415,4369,0,29.9963722,30.0600128,-0.504,-0.504,,29.9595625,,,,,,,,,,,,,,,,,,,,,,,30.0098889
,9390957.15,30.0110187625,-0.504,1778.29962721342,7.99868293462816,,2.40054616325148E-8,2.66902349961019E-5,4.85460007351777E-6,2.71281364273505E-5,10.3086493175394,1.47683535364813E-8,-5.9249881493365E-10,1.47802341329289E-8,-2.2974453574173,66,25,5,13.4965986394558,0.621359593016433,0.000828648257249251,4369,0,29.9966755,30.0586376,-0.504,-0.504,,29.9550125,,,,,,,,,,,,,,,,,,,,,,,30.0110187625
,9391868.37,35.024281025,-0.504,13.3350419384902,9.99906386271125,,2.47059825039371E-7,3.86939836017678E-5,8.39919366538792E-7,3.8703098474362E-5,1.24350801174768,1.47508410229496E-8,5.5884669208695E-11,1.47509468842032E-8,0.217068325849911,6400,25,5,13.4965986394558,0.621359593016433,8.98602406559815E-5,4369,0,35.0101738,35.0699081,-0.504,-0.504,,34.962225,,,,,,,,,,,,,,,,,,,,,,,35.024281025
,9392394.18,35.0190754,-0.504,56.2339235787512,9.99906017010521,,6.67033906932488E-8,3.85263985960758E-5,9.72864902477192E-7,3.85386799839095E-5,1.44652008982976,1.47866761047617E-8,6.30788595624495E-11,1.47868106490093E-8,0.244418047738804,1600,25,5,13.4965986394558,0.621359593016433,0.000108430433960025,4369,0,35.0097847,35.0635872,-0.504,-0.504,,34.954425,,,,,,,,,,,,,,,,,,,,,,,35.0190754
,9392685.77,35.0113863875,-0.504,177.830382106244,9.99873928551428,,4.66380643750449E-8,3.78348313515077E-5,2.58492204149987E-6,3.79230310676463E-5,3.90844415359561,1.47839501725468E-8,-3.82634336280037E-11,1.47839996886736E-8,-0.148291108653382,400,25,5,13.4965986394558,0.621359593016433,0.000171059478435759,4369,0,34.9988632,35.0533485,-0.504,-0.504,,34.9439625,,,,,,,,,,,,,,,,,,,,,,,35.0113863875
,9392910.66,35.01143505,-0.504,1000,10.0004978030546,,1.20356777181274E-8,3.22556042514718E-5,5.46972332360126E-6,3.2716079821157E-5,9.62434105984903,1.48029387852871E-8,-2.87228634887147E-10,1.48057251416354E-8,-1.11159844089411,66,25,5,13.4965986394558,0.621359593016433,0.000617776593692364,4369,0,34.9975243,35.0537796,-0.504,-0.504,,34.9413125,,,,,,,,,,,,,,,,,,,,,,,35.01143505
,9393114.35,35.023041725,-0.504,10000,10.0003729181568,,1.0004919083042E-7,2.61167613623735E-5,4.10867478367719E-6,2.64379733061592E-5,8.94046456220465,1.4501640981207E-8,-3.24546028094806E-9,1.4860370237078E-8,-12.6148985334269,11,5,5,13.4965986394558,0.621359593016433,0.00423769219363694,4369,0,35.0082741,35.0645065,-0.504,-0.504,,34.9241125,,,,,,,,,,,,,,,,,,,,,,,35.023041725
,9394517.65,40.0165791625,-0.504,42.1700838769804,9.99982594663498,,8.93646519394428E-8,3.42806193855248E-5,6.29509124426986E-7,3.42863988659199E-5,1.05202774088473,1.4752113195563E-8,5.69564858317695E-11,1.47522231469017E-8,0.221212377897011,1600,25,5,13.4965986394558,0.621359593016433,0.000104412109734295,4369,0,40.008812,40.0583,-0.504,-0.504,,39.9472,,,,,,,,,,,,,,,,,,,,,,,40.0165791625
,9394838.21,40.0088262625,-0.504,133.349953401678,9.9996462639895,,7.06572179070683E-8,3.41397032179799E-5,1.52236434419351E-6,3.41736291459982E-5,2.55325318742385,1.47568465576007E-8,-2.04554904485797E-11,1.47568607349823E-8,-0.0794216105276178,800,25,5,13.4965986394558,0.621359593016433,0.000145637787291897,4369,0,39.9974022,40.0482941,-0.504,-0.504,,39.9424125,,,,,,,,,,,,,,,,,,,,,,,40.0088262625
,9395072.44,40.009336475,-0.504,562.339235787512,10.0005074875847,,2.42806014351539E-8,3.16355616864768E-5,3.84480194944076E-6,3.18683426812456E-5,6.92941166437786,1.47665590539301E-8,-1.46715261075098E-10,1.47672878911815E-8,-0.56925168720494,200,25,5,13.4965986394558,0.621359593016433,0.000376529106140939,4369,0,39.9965858,40.0422974,-0.504,-0.504,,39.9396625,,,,,,,,,,,,,,,,,,,,,,,40.009336475
,9395278.57,40.0148616125,-0.504,5623.39981360671,10.0001345673021,,4.79635402517844E-8,2.42380075444267E-5,3.19464021812235E-6,2.44476325202857E-5,7.50847168245362,1.46544979303713E-8,-1.82741307176708E-9,1.47679974311388E-8,-7.10808057536053,18,5,5,13.4965986394558,0.621359593016433,0.00284534168612104,4369,0,40.0012169,40.0514908,-0.504,-0.504,,39.9301125,,,,,,,,,,,,,,,,,,,,,,,40.0148616125
,9396413.35,45.01623155,-0.504,31.6230195712954,10.0010061615809,,1.13120771684037E-7,3.0244041879899E-5,3.55875049319261E-7,3.02461355595027E-5,0.674155837556053,1.47485390391335E-8,6.01602939287177E-11,1.47486617375886E-8,0.23371208564004,3200,25,5,13.4965986394558,0.621359593016433,0.000101647145938863,4369,0,45.0073662,45.0524025,-0.504,-0.504,,44.9297125,,,,,,,,,,,,,,,,,,,,,,,45.01623155
,9396773.40,45.0105824125,-0.504,100,10.0009242179225,,6.0541345803012E-8,3.05059975292767E-5,8.23083936649695E-7,3.05170993448428E-5,1.5455255016373,1.47691340035279E-8,9.39729947055369E-11,1.47694329660248E-8,0.364556467864273,800,25,5,13.4965986394558,0.621359593016433,0.000130396642156621,4369,0,45.0000381,45.0490494,-0.504,-0.504,,44.9320625,,,,,,,,,,,,,,,,,,,,,,,45.0105824125
,9397024.21,45.012571325,-0.504,370,9.99952004286801,,5.87825210081322E-8,2.9747058016268E-5,2.30017548921508E-6,2.98358554076199E-5,4.42156748675818,1.47624634804389E-8,-9.06535325375481E-11,1.47627418210254E-8,-0.351838264123785,200,25,5,13.4965986394558,0.621359593016433,0.000270040626970987,4369,0,44.9997597,45.0452843,-0.504,-0.504,,44.9193875,,,,,,,,,,,,,,,,,,,,,,,45.012571325
,9397233.50,45.0116038125,-0.504,3162.30009319665,9.99914506258726,,2.39438561196568E-8,2.3540856953617E-5,3.75045960152421E-6,2.38377409444209E-5,9.05211876479375,1.47414186322226E-8,-1.03083102650037E-9,1.47774164147741E-8,-4.00004106847996,28,25,5,13.4965986394558,0.621359593016433,0.00173312859998442,4369,0,44.9992599,45.0456543,-0.504,-0.504,,44.91245,,,,,,,,,,,,,,,,,,,,,,,45.0116038125
,9398439.97,50.0179076125,-0.504,17.7830848089469,9.99835374353676,,2.30113440626777E-7,2.88101111819933E-5,1.17917615519389E-7,2.8810352494943E-5,0.234506001404024,1.47169991384899E-8,6.04867731598384E-11,1.47171234380921E-8,0.235483964639021,6400,25,5,13.4965986394558,0.621359593016433,8.90981031995485E-5,4369,0,50.0034561,50.0570259,-0.504,-0.504,,49.906875,,,,,,,,,,,,,,,,,,,,,,,50.0179076125
,9398862.94,50.008802875,-0.504,74.9888164026095,9.99836726262415,,1.86816078217595E-7,2.77638169146485E-5,4.64644188245944E-7,2.77677046925343E-5,0.958789852774297,1.47620455097102E-8,8.34963198610744E-11,1.47622816416089E-8,0.324069974875005,1600,25,5,13.4965986394558,0.621359593016433,0.000121269438603342,4369,0,49.9969215,50.0370865,-0.504,-0.504,,49.9114125,,,,,,,,,,,,,,,,,,,,,,,50.008802875
,9399136.02,50.01105975,-0.504,237.139794967381,10.00197032786,,4.22705227361644E-8,2.76931947249611E-5,9.90885274391602E-7,2.77109163995278E-5,2.04921587870766,1.47601932793015E-8,-5.12851816170588E-11,1.47602823757607E-8,-0.199076839843826,400,25,5,13.4965986394558,0.621359593016433,0.000200914928091822,4369,0,50.000267,50.0377541,-0.504,-0.504,,49.8987375,,,,,,,,,,,,,,,,,,,,,,,50.01105975
,9399354.54,50.0114584125,-0.504,1778.29962721342,10.0010044601859,,1.71299753293539E-8,2.46204286640115E-5,3.76094937768859E-6,2.49060283429778E-5,8.68520616147974,1.47607331527296E-8,-5.66660859435561E-10,1.47716061325676E-8,-2.19849106523782,66,25,5,13.4965986394558,0.621359593016433,0.00102809948791168,4369,0,49.9958992,50.0400772,-0.504,-0.504,,49.89095,,,,,,,,,,,,,,,,,,,,,,,50.0114584125
,9400267.34,55.0452146625,-0.504,13.3350419384902,10.0001032549913,,3.68934463601822E-7,2.63240981966171E-5,-4.25948862530828E-7,2.63275440992629E-5,-0.927019126226639,1.47021913882038E-8,5.41980552847205E-11,1.470229128553E-8,0.211213803247256,6400,25,5,13.4965986394558,0.621359593016433,8.13387050045209E-5,4369,0,55.0340195,55.0841713,-0.504,-0.504,,54.8854125,,,,,,,,,,,,,,,,,,,,,,,55.0452146625
,9400795.83,55.011376375,-0.504,56.2339235787512,10.0003370344583,,7.88519241952654E-8,2.55611002283753E-5,8.09083516481183E-8,2.55612282773425E-5,0.181357279367517,1.47510490080923E-8,8.00960195862421E-11,1.47512664612736E-8,0.311104571284453,1600,25,5,13.4965986394558,0.621359593016433,0.000114736854748108,4369,0,55.0023651,55.0431633,-0.504,-0.504,,54.901225,,,,,,,,,,,,,,,,,,,,,,,55.011376375
,9401083.85,55.0075936125,-0.504,177.830382106244,10.0000470298265,,4.79292419398783E-8,2.55044079371454E-5,4.44787040838251E-7,2.55082860995407E-5,0.999115021391552,1.47594087377572E-8,-2.99176820525831E-11,1.47594390596622E-8,-0.116139785621783,400,25,5,13.4965986394558,0.621359593016433,0.000171535543672146,4369,0,54.9969711,55.0340347,-0.504,-0.504,,54.8869625,,,,,,,,,,,,,,,,,,,,,,,55.0075936125
,9401309.50,55.00740145,-0.504,1000,10.0018643682064,,1.53381652558784E-8,2.4945058842494E-5,1.64414960769239E-6,2.49991837584342E-5,3.77095822049023,1.47850599217201E-8,-2.72902778342746E-10,1.4787578328289E-8,-1.0574459706873,66,25,5,13.4965986394558,0.621359593016433,0.000598342026580851,4369,0,54.9965248,55.0309105,-0.504,-0.504,,54.8840375,,,,,,,,,,,,,,,,,,,,,,,55.00740145
,9401513.63,55.0138716625,-0.504,10000,9.99985970619607,,1.08578625995136E-7,1.95653211918052E-5,3.07381693876465E-6,1.98053059534948E-5,8.92849374752291,1.44846047292082E-8,-3.29033874995148E-9,1.48536225632279E-8,-12.7981843059771,11,5,5,13.4965986394558,0.621359593016433,0.00475773601226312,4369,0,55.0022774,55.0392036,-0.504,-0.504,,54.8726,,,,,,,,,,,,,,,,,,,,,,,55.0138716625
,9402709.41,60.021731875,-0.504,42.1700838769804,9.99887745549509,,9.07363182782344E-8,2.31970490125454E-5,-9.35541098243579E-8,2.31972376644698E-5,-0.231073641500245,1.47355700054253E-8,8.02771982351642E-11,1.47357886729332E-8,0.312135814610401,1600,25,5,13.4965986394558,0.621359593016433,0.000105740216256291,4369,0,60.0106621,60.054821,-0.504,-0.504,,59.886725,,,,,,,,,,,,,,,,,,,,,,,60.021731875
,9403028.18,60.0111804,-0.504,133.349953401678,9.99876422841965,,6.2721638846128E-8,2.36993813340673E-5,9.26477007807482E-8,2.36995624266355E-5,0.223984547116125,1.47564646290063E-8,-1.12791310270746E-11,1.4756468939618E-8,-0.043794126494447,800,25,5,13.4965986394558,0.621359593016433,0.000151486588767509,4369,0,59.9988251,60.0369797,-0.504,-0.504,,59.8586125,,,,,,,,,,,,,,,,,,,,,,,60.0111804
,9403259.97,60.005992875,-0.504,562.339235787512,9.99962759466712,,2.11113874489873E-8,2.34513703456165E-5,4.7723676371358E-7,2.34562257410671E-5,1.16581156502185,1.47681566503926E-8,-1.44001391932354E-10,1.47688586983359E-8,-0.558662176038979,200,25,5,13.4965986394558,0.621359593016433,0.000369685828767213,4369,0,59.9949951,60.0284767,-0.504,-0.504,,59.8551,,,,,,,,,,,,,,,,,,,,,,,60.005992875
,9403462.78,60.0085110375,-0.504,5623.39981360671,10.0018897872794,,4.09445437886352E-8,2.18850940521267E-5,2.53408337592451E-6,2.20313168064591E-5,6.60488678766034,1.46787895142449E-8,-1.84705686532709E-9,1.47945422594705E-8,-7.17193064885475,18,5,5,13.4965986394558,0.621359593016433,0.00295762122300478,4369,0,59.999752,60.0340195,-0.504,-0.504,,59.8443625,,,,,,,,,,,,,,,,,,,,,,,60.0085110375
,9404993.19,70.0036354,-0.504,31.6230195712954,9.99993074548467,,1.04649577314119E-7,2.04805389553937E-5,-1.73129903106014E-7,2.04812707092785E-5,-0.484331808987747,1.47090032732824E-8,7.44195017291594E-11,1.47091915330405E-8,0.28988279499069,3200,25,5,13.4965986394558,0.621359593016433,9.24071816506852E-5,4369,0,69.9952621,70.0264664,-0.504,-0.504,,69.84345,,,,,,,,,,,,,,,,,,,,,,,70.0036354
,9405352.98,70.0077104625,-0.504,100,9.99981094658806,,4.63534199164482E-8,2.05404883197917E-5,-1.48926444096334E-8,2.05404937186611E-5,-0.0415416375529958,1.47629852572741E-8,1.11171776970666E-10,1.47634038375467E-8,0.431454283240569,800,25,5,13.4965986394558,0.621359593016433,0.000136653820347814,4369,0,69.9969101,70.0249939,-0.504,-0.504,,69.843225,,,,,,,,,,,,,,,,,,,,,,,70.0077104625
,9405607.18,70.00732515,-0.504,370,9.99840844427183,,4.52942203935128E-8,2.05435058647535E-5,7.60603805694077E-8,2.05436466674408E-5,0.212131216115218,1.47638068148906E-8,-8.55189497446708E-11,1.47640544959092E-8,-0.331880533922345,200,25,5,13.4965986394558,0.621359593016433,0.000272526175118916,4369,0,69.9989166,70.0262451,-0.504,-0.504,,69.8325125,,,,,,,,,,,,,,,,,,,,,,,70.00732515
,9405817.43,70.00515555,-0.504,3162.30009319665,9.99942136806114,,2.13609772698416E-8,2.03627519568634E-5,3.78342373792625E-7,2.03662664769111E-5,1.06443997807596,1.47514029276154E-8,-1.03077584831088E-9,1.47873725584473E-8,-3.99712919668599,28,25,5,13.4965986394558,0.621359593016433,0.00173510838610417,4369,0,69.9938812,70.0312424,-0.504,-0.504,,69.8300375,,,,,,,,,,,,,,,,,,,,,,,70.00515555
,9407224.16,80.0225849125,-0.504,17.7830848089469,10.000403444836,,1.2626967978389E-7,1.80084862312699E-5,9.76790177978115E-8,1.80087511374985E-5,0.310772405367959,1.46740656448072E-8,4.79064874094017E-11,1.46741438448602E-8,0.18705312178558,6400,25,5,13.4965986394558,0.621359593016433,7.95258315820292E-5,4369,0,80.0164185,80.0426559,-0.504,-0.504,,79.7644125,,,,,,,,,,,,,,,,,,,,,,,80.0225849125
,9407650.53,80.0042658,-0.504,74.9888164026095,10.0005252490945,,1.41438711064075E-7,1.81070857393203E-5,-7.29035263525393E-8,1.81072325023801E-5,-0.23068548197233,1.4741494060187E-8,1.02749308013746E-10,1.47418521409905E-8,0.399349369895847,1600,25,5,13.4965986394558,0.621359593016433,0.000118864892121308,4369,0,79.9959106,80.0188446,-0.504,-0.504,,79.784675,,,,,,,,,,,,,,,,,,,,,,,80.0042658
,9407917.66,80.009343125,-0.504,237.139794967381,9.99988843495038,,3.00457716845203E-8,1.80599346677644E-5,4.40134269090057E-8,1.80599882997102E-5,0.139633872305071,1.47593588518416E-8,-4.07592489247495E-11,1.47594151318339E-8,-0.158226859735805,400,25,5,13.4965986394558,0.621359593016433,0.000206974173499422,4369,0,80.0027847,80.0284424,-0.504,-0.504,,79.770575,,,,,,,,,,,,,,,,,,,,,,,80.009343125
,9408133.97,80.0034275125,-0.504,1778.29962721342,9.99957433992272,,2.31617142140828E-8,1.80632310821974E-5,4.64204169544779E-8,1.80632907296532E-5,0.147243209562279,1.47638486926421E-8,-5.65616480836298E-10,1.47746793610766E-8,-2.19398049381323,66,25,5,13.4965986394558,0.621359593016433,0.00101100577902368,4369,0,79.9963608,80.0225372,-0.504,-0.504,,79.7806875,,,,,,,,,,,,,,,,,,,,,,,80.0034275125
,9409406.09,90.0805597375,-0.504,13.3350419384902,9.99882701893472,,8.02835549878095E-8,1.59614608420799E-5,1.09606661710068E-7,1.59618371697478E-5,0.393441457277055,1.46833370448955E-8,3.63968854603766E-11,1.46833821549149E-8,0.142023822431731,6400,25,5,13.4965986394558,0.621359593016433,7.63295940654606E-5,4369,0,90.0700455,90.0920486,-0.504,-0.504,,89.7065875,,,,,,,,,,,,,,,,,,,,,,,90.0805597375
,9409958.61,90.004174225,-0.504,56.2339235787512,9.99949165762373,,7.0591313073983E-8,1.64100923941243E-5,-1.14264781079305E-7,1.64104902066907E-5,-0.398948631193605,1.47248349455967E-8,8.90453235191128E-11,1.47251041845111E-8,0.346479879151925,1600,25,5,13.4965986394558,0.621359593016433,0.000102429413512266,4369,0,89.9991684,90.0175095,-0.504,-0.504,,89.7496125,,,,,,,,,,,,,,,,,,,,,,,90.004174225
,9410276.10,90.007670375,-0.504,177.830382106244,9.99919175238355,,4.31720280044409E-8,1.62095536064566E-5,-5.20808807405757E-8,1.62096372735089E-5,-0.184089239227205,1.47532464863907E-8,-1.43132718656906E-11,1.47532534295982E-8,-0.0555870745047287,400,25,5,13.4965986394558,0.621359593016433,0.000175328025629402,4369,0,90.0021133,90.0275497,-0.504,-0.504,,89.7421,,,,,,,,,,,,,,,,,,,,,,,90.007670375
,9410528.81,90.00520325,-0.504,1000,10.0011771872653,,8.12855326427625E-9,1.61735544234063E-5,3.48529233401969E-8,1.6173591976217E-5,0.123468364946452,1.47877883447516E-8,-2.71010022175038E-10,1.47902714836913E-8,-1.04991984329081,66,25,5,13.4965986394558,0.621359593016433,0.000595375124878954,4369,0,90.0010605,90.0234146,-0.504,-0.504,,89.7192125,,,,,,,,,,,,,,,,,,,,,,,90.00520325
,9410758.76,90.0067644125,-0.504,10000,9.99940084671598,,8.77017745610629E-8,1.63868860994736E-5,5.42427395845104E-8,1.63869758745145E-5,0.189655842949576,1.4508505168368E-8,-3.34499152852056E-9,1.48891131551357E-8,-12.9828990491759,11,5,5,13.4965986394558,0.621359593016433,0.00481361330906033,4369,0,90.0003052,90.021843,-0.504,-0.504,,89.7057625,,,,,,,,,,,,,,,,,,,,,,,90.0067644125