File: FSS2_60D_ScanT_0.25T.dat
[Header]
; ACMS Data File (default extension .dat)
; Copyright 1999, Quantum Design, Inc. All rights reserved.
TITLE,
FILEOPENTIME,9477419.64,04-21-2021,1:57 am
BYAPP,ACMS,1.0,1.1
INFO,PPMS ACMS Option Version: 1.0.9 Build 14,APPNAME
INFO,HARMONICS,1
DATATYPE,COMMENT,1
DATATYPE,TIME,2
FIELDGROUP,AC Mag,2,3,4,5,6,8,9,10,11,12
FIELDGROUP,DC Mag,2,3,4,7,8
STARTUPGROUP,All
STARTUPAXIS,X,2,LINEAR,AUTO
TIMEMODE,MINUTES,RELATIVE
PLOT_APPEARANCE,ALL,HORZ_GRID_ON,VERT_GRID_ON,MARKERS_AND_LINES
RECORDS,ALL_RECORDS
DATATYPE,TIME,2
DATATYPE,COMMENT,1
[Data]
Comment,Time Stamp (sec),Temperature (K),Magnetic Field (Oe),Frequency (Hz),Amplitude (Oe),M-DC (emu),M-Std.Dev. (emu),M' (emu),M'' (emu),Moment (emu),Phase (deg),Calcoil' (emu),Calcoil'' (emu),Calcoil (emu),CC Phase (deg),Count,Gain,Measure Type,Elapsed (sec),Sample Center (cm),Max.Signal (V),PPMS Status (code),DSP Status (code),Min.Temperature (K),Max.Temperature (K),Min.Field (Oe),Max.Field (Oe),DC Position (cm),PPMS Temperature (K),PPMS Position,Bridge 1 Resistance (ohms),Bridge 1 Excitation (uA),Bridge 2 Resistance (ohms),Bridge 2 Excitation (uA),Bridge 3 Resistance (ohms),Bridge 3 Excitation (uA),Bridge 4 Resistance (ohms),Bridge 4 Excitation (uA),Signal 1 Vin (V),Signal 2 Vin (V),Digital Inputs (code),Drive 1 Iout (mA),Drive 1 Ipower (watts),Drive 2 Iout (mA),Drive 2 Ipower (watts),Pressure (),Map 20 (),Map 21 (),Map 22 (),Map 23 (),Map 24 (),Map 25 (),Map 26 (),Map 27 (),Map 28 (),Map 29 ()
,9479987.82,7.4923606625,2499.175,10,6.00079423145365,,6.7390710282194E-7,5.67546747080206E-5,2.24788385045509E-5,6.1044174838611E-5,21.6070453145344,1.47618012089455E-8,1.14004379031167E-10,1.47622414263845E-8,0.442482581436871,6400,25,5,13.4965986394558,0.621359593016433,8.23324591056112E-5,4369,0,7.4892097,7.494256,2499.175,2499.175,,7.5239125,,,,,,,,,,,,,,,,,,,,,,,7.4923606625
,9480316.08,7.49722735,2499.175,39.8108108108108,6.00078428340379,,1.59636181108636E-7,2.71371493993207E-5,2.56529609586277E-5,3.73429951057213E-5,43.3895593749041,1.47357089442841E-8,5.0145905945018E-11,1.47357942677867E-8,0.194977906429641,1600,25,5,13.4965986394558,0.621359593016433,8.73342317749396E-5,4369,0,7.4958205,7.4996958,2499.175,2499.175,,7.5292,,,,,,,,,,,,,,,,,,,,,,,7.49722735
,9480469.86,7.4990582875,2499.175,158.490214352283,6.00062662274035,,5.55994597845137E-8,8.49313544386407E-6,1.24235565021997E-5,1.50491895406752E-5,55.6422556952988,1.47584148038191E-8,-3.02889218655522E-11,1.47584458849967E-8,-0.117588845105217,400,25,5,13.4965986394558,0.621359593016433,0.000123332334494573,4369,0,7.4974322,7.5002007,2499.175,2499.175,,7.5309375,,,,,,,,,,,,,,,,,,,,,,,7.4990582875
,9480579.76,7.4993833375,2499.175,630.960391425909,5.99812947141829,,3.25422720470528E-8,4.62421226890913E-6,3.8817221492366E-6,6.03747513053294E-6,40.0112488201731,1.4768958898049E-8,-1.70939371444667E-10,1.47699481109776E-8,-0.663125091644702,66,25,5,13.4965986394558,0.621359593016433,0.000270761860165834,4369,0,7.49862,7.5001469,2499.175,2499.175,,7.5323875,,,,,,,,,,,,,,,,,,,,,,,7.4993833375
,9480678.40,7.5028128125,2499.175,2511.90074557316,6.00047446050539,,2.32155076771346E-8,3.93667059255758E-6,1.25948898056929E-6,4.13324180837308E-6,17.7414289264841,1.47418710849532E-8,-8.20932425582378E-10,1.47647110751532E-8,-3.187345273934,40,25,5,13.4965986394558,0.621359593016433,0.000757886873965232,4369,0,7.5010004,7.5043259,2499.175,2499.175,,7.5309625,,,,,,,,,,,,,,,,,,,,,,,7.5028128125
,9480777.41,7.5122897125,2499.175,10000,6.00062078406639,,4.09003710676817E-8,3.61769082401604E-6,5.08155341004183E-7,3.65320527054817E-6,7.9956831846028,1.450044479939E-8,-3.26965344353406E-9,1.48645058115287E-8,-12.7069078316848,11,5,5,13.4965986394558,0.621359593016433,0.00212928663557285,4369,0,7.5095568,7.5147457,2499.175,2499.175,,7.521525,,,,,,,,,,,,,,,,,,,,,,,7.5122897125
,9481351.31,7.9975229,2499.175,28.1840633737185,6.00078957972701,,4.26731873917825E-7,3.97281462535432E-5,2.53527201354625E-5,4.71283993257782E-5,32.5441919152026,1.47492602857016E-8,4.68900971980534E-11,1.47493348208179E-8,0.182151210790203,3200,25,5,13.4965986394558,0.621359593016433,8.51909758151674E-5,4369,0,7.9944439,7.9989152,2499.175,2499.175,,8.0315,,,,,,,,,,,,,,,,,,,,,,,7.9975229
,9481531.15,8.0009644,2499.175,112.199906803355,6.00071056444864,,8.69680089408669E-8,1.41811051473687E-5,1.80330870969394E-5,2.29411415026918E-5,51.8187144134206,1.47596188733192E-8,-1.68679382757575E-11,1.4759628512025E-8,-0.0654800953751646,800,25,5,13.4965986394558,0.621359593016433,0.000108070979042659,4369,0,7.9998398,8.002368,2499.175,2499.175,,8.027375,,,,,,,,,,,,,,,,,,,,,,,8.0009644
,9481647.35,8.0010779,2499.175,446.679869524697,5.9994586295659,,9.56266865812179E-9,5.32746708752316E-6,6.61852730102153E-6,8.49628208118174E-6,51.1682852087173,1.4764684233363E-8,-1.17472760090306E-10,1.47651515522287E-8,-0.455854743319719,200,25,5,13.4965986394558,0.621359593016433,0.0002156870655616,4369,0,7.9988413,8.0022783,2499.175,2499.175,,8.0270375,,,,,,,,,,,,,,,,,,,,,,,8.0010779
,9481748.76,8.002682225,2499.175,1778.29962721342,6.00055142792286,,1.92121655886608E-8,3.95688012388004E-6,2.01207627153964E-6,4.43907098808408E-6,26.9533677360629,1.47522222070676E-8,-5.76667468948687E-10,1.47634889310232E-8,-2.23856432791115,66,25,5,13.4965986394558,0.621359593016433,0.00058605835361061,4369,0,8.0017204,8.0052624,2499.175,2499.175,,8.0273875,,,,,,,,,,,,,,,,,,,,,,,8.002682225
,9481844.33,8.0103700125,2499.175,7079.5,5.9991915094299,,7.21142363369217E-8,3.68498366176876E-6,5.74013079378655E-7,3.72942295842137E-6,8.85385883332019,1.46210782464974E-8,-2.31282505563277E-9,1.48028743434565E-8,-8.98881318746936,15,5,5,13.4965986394558,0.621359593016433,0.00167191715722345,4369,0,8.0081987,8.0135393,2499.175,2499.175,,8.0210625,,,,,,,,,,,,,,,,,,,,,,,8.0103700125
,9482371.09,8.4963967875,2499.175,19.952935694315,6.00079223420573,,4.22600449655585E-7,4.96388265902134E-5,2.01690058069371E-5,5.35798646927513E-5,22.1126508496376,1.47537002698468E-8,5.29111077478712E-11,1.47537951469377E-8,0.205478633228277,3200,25,5,13.4965986394558,0.621359593016433,8.33158273495398E-5,4369,0,8.4952793,8.4975691,2499.175,2499.175,,8.5259875,,,,,,,,,,,,,,,,,,,,,,,8.4963967875
,9482582.81,8.4985705625,2499.175,79.4333643988816,6.0007526303336,,8.02688953068441E-8,2.31729503153175E-5,2.26960583358495E-5,3.24360399910417E-5,44.4043273648464,1.47597693184464E-8,7.3643866227361E-11,1.47599530403312E-8,0.285874908781733,800,25,5,13.4965986394558,0.621359593016433,9.84511891211369E-5,4369,0,8.4975691,8.4996424,2499.175,2499.175,,8.5288625,,,,,,,,,,,,,,,,,,,,,,,8.4985705625
,9482707.05,8.4993458875,2499.175,316.22972972973,6.00012505209523,,2.54846443753652E-8,7.36963510080188E-6,1.06697400926067E-5,1.29674544596367E-5,55.3669965351713,1.47621521930639E-8,-7.77494895608737E-11,1.47623569376407E-8,-0.301763344754079,200,25,5,13.4965986394558,0.621359593016433,0.000175081652245611,4369,0,8.4981594,8.500123,2499.175,2499.175,,8.52865,,,,,,,,,,,,,,,,,,,,,,,8.4993458875
,9482808.25,8.49963345,2499.175,1258.90027958993,5.99855311901706,,2.4010045892168E-8,4.02497327152994E-6,3.28915864195124E-6,5.19797791534871E-6,39.255271292844,1.47561195852868E-8,-4.03193589634452E-10,1.47616269525417E-8,-1.5651502672647,66,25,5,13.4965986394558,0.621359593016433,0.000452322245834249,4369,0,8.4986372,8.5008211,2499.175,2499.175,,8.5280375,,,,,,,,,,,,,,,,,,,,,,,8.49963345
,9482905.65,8.5071951125,2499.175,5011.89934762349,6.00179066931923,,2.23550401818391E-8,3.5476010268578E-6,1.02580238114962E-6,3.69293156867748E-6,16.1274273190057,1.46851522685918E-8,-1.64669915128261E-9,1.47771890170817E-8,-6.39805570764156,18,25,5,13.4965986394558,0.621359593016433,0.00127195962469486,4369,0,8.5046396,8.50945,2499.175,2499.175,,8.5258875,,,,,,,,,,,,,,,,,,,,,,,8.5071951125
,9483369.77,8.993665225,2499.175,14.1251164958061,6.000793564728,,4.94326904972507E-7,5.43716998764503E-5,1.46771408117197E-5,5.63178498334394E-5,15.1064142723034,1.47727570690371E-8,6.80360188677348E-11,1.47729137383473E-8,0.263874181178841,6400,25,5,13.4965986394558,0.621359593016433,8.21929517810332E-5,4369,0,8.9922791,8.996192,2499.175,2499.175,,9.02735,,,,,,,,,,,,,,,,,,,,,,,8.993665225
,9483632.78,8.99755525,2499.175,56.2339235787512,6.00077371602089,,1.50808541907684E-7,3.39776479844433E-5,2.31091328579392E-5,4.10915147445385E-5,34.2206972849167,1.47564875006133E-8,5.73834980174389E-11,1.47565990736891E-8,0.222804761450791,1600,25,5,13.4965986394558,0.621359593016433,9.21588834748338E-5,4369,0,8.9965019,8.9991941,2499.175,2499.175,,9.03115,,,,,,,,,,,,,,,,,,,,,,,8.99755525
,9483769.78,8.9989885125,2499.175,223.869990680336,6.0004591650216,,3.94693675410434E-8,1.17002727333713E-5,1.53953694289189E-5,1.93368503611152E-5,52.7656567792175,1.47573368307399E-8,-5.15733352011859E-11,1.47574269486525E-8,-0.200234123985126,400,25,5,13.4965986394558,0.621359593016433,0.000145726648525373,4369,0,8.99751,9.000555,2499.175,2499.175,,9.03145,,,,,,,,,,,,,,,,,,,,,,,8.9989885125
,9483876.44,8.9997433625,2499.175,891.250232991612,5.99965815630419,,1.61133157172657E-8,4.58612581147825E-6,5.34283501232601E-6,7.04119563196789E-6,49.3582196900908,1.47771734713165E-8,-2.48755745981612E-10,1.47792670732529E-8,-0.96441368458062,66,25,5,13.4965986394558,0.621359593016433,0.000346295366796712,4369,0,8.9992018,9.0002556,2499.175,2499.175,,9.03235,,,,,,,,,,,,,,,,,,,,,,,8.9997433625
,9483974.50,9.0036611375,2499.175,3548.09972041007,6.00061147554465,,2.96058199957082E-8,3.52859016585382E-6,1.67254868124548E-6,3.90491583132035E-6,25.3609112442298,1.47209084557565E-8,-1.16378848124604E-9,1.47668395194044E-8,-4.52022172328583,28,25,5,13.4965986394558,0.621359593016433,0.000979352531920605,4369,0,9.002636,9.004981,2499.175,2499.175,,9.0297125,,,,,,,,,,,,,,,,,,,,,,,9.0036611375
,9484376.09,9.9894850625,2499.175,10,6.00079423145365,,4.962606180201E-7,5.38578148632881E-5,1.04538535676297E-5,5.48629863957629E-5,10.9845763962797,1.47692561891804E-8,1.17493441077677E-10,1.47697235278911E-8,0.455793859988558,6400,25,5,13.4965986394558,0.621359593016433,8.32281691111013E-5,4369,0,9.9883633,9.9909325,2499.175,2499.175,,10.0272,,,,,,,,,,,,,,,,,,,,,,,9.9894850625
,9484706.74,9.9969412125,2499.175,39.8108108108108,6.00078428340379,,1.71188224820767E-7,4.38972874329956E-5,1.72833703479529E-5,4.7177184470457E-5,21.4906991566004,1.47379064983432E-8,4.85000700806351E-11,1.4737986301076E-8,0.18855047633763,1600,25,5,13.4965986394558,0.621359593016433,8.79934730557855E-5,4369,0,9.9963608,9.9974489,2499.175,2499.175,,10.0341375,,,,,,,,,,,,,,,,,,,,,,,9.9969412125
,9484861.42,9.9979400625,2499.175,158.490214352283,6.00062662274035,,5.48798761970822E-8,2.16403391853192E-5,2.00007513989344E-5,2.94675132404762E-5,42.7451849309259,1.47589788662224E-8,-3.09758787662049E-11,1.47590113719946E-8,-0.120251172536712,400,25,5,13.4965986394558,0.621359593016433,0.000124149087925733,4369,0,9.9975767,9.9981823,2499.175,2499.175,,10.036025,,,,,,,,,,,,,,,,,,,,,,,9.9979400625
,9484969.82,9.9989072125,2499.175,630.960391425909,5.99812947141829,,3.98716531204058E-8,6.75296165013856E-6,9.72164964094186E-6,1.18369321527779E-5,55.2149483550033,1.47683743838446E-8,-1.71509612581544E-10,1.47693702468523E-8,-0.665363360376602,66,25,5,13.4965986394558,0.621359593016433,0.000272286139939286,4369,0,9.9983063,9.9995775,2499.175,2499.175,,10.0363,,,,,,,,,,,,,,,,,,,,,,,9.9989072125
,9485069.41,10.00150655,2499.175,2511.90074557316,6.00047446050539,,2.15864492627919E-8,3.62179232736684E-6,2.98472620871104E-6,4.69318337629586E-6,39.4920023382834,1.47411578463362E-8,-8.2080461786476E-10,1.47639918338946E-8,-3.1870039469033,40,25,5,13.4965986394558,0.621359593016433,0.000758252584456796,4369,0,10.0004168,10.0021133,2499.175,2499.175,,10.0353,,,,,,,,,,,,,,,,,,,,,,,10.00150655
,9485165.95,10.0098177125,2499.175,10000,6.00062078406639,,3.67516504287679E-8,3.15821715063103E-6,9.08274178826578E-7,3.28622846960815E-6,16.0447481580332,1.45010165113304E-8,-3.26841958233772E-9,1.48647921757448E-8,-12.7017837194718,11,5,5,13.4965986394558,0.621359593016433,0.00213033652215151,4369,0,10.0084391,10.0105257,2499.175,2499.175,,10.02825,,,,,,,,,,,,,,,,,,,,,,,10.0098177125
,9485973.11,11.0006946375,2499.175,28.1840633737185,6.00078957972701,,4.27520672881192E-7,4.54215966896225E-5,1.07620379970047E-5,4.66791485321197E-5,13.329656908454,1.47441490562486E-8,4.63079280924439E-11,1.47442217772618E-8,0.17995206799483,3200,25,5,13.4965986394558,0.621359593016433,8.5537839384469E-5,4369,0,10.999136,11.0036802,2499.175,2499.175,,10.9975875,,,,,,,,,,,,,,,,,,,,,,,11.0006946375
,9486155.30,11.0029861875,2499.175,112.199906803355,6.00071056444864,,7.64680754103641E-8,3.21163767849708E-5,1.87565325522517E-5,3.71923267782198E-5,30.285684631472,1.47572526510113E-8,-1.64729527927962E-11,1.47572618450699E-8,-0.0639570454914065,800,25,5,13.4965986394558,0.621359593016433,0.000109342624997536,4369,0,11.0019636,11.0057516,2499.175,2499.175,,10.997325,,,,,,,,,,,,,,,,,,,,,,,11.0029861875
,9486276.44,11.0033588125,2499.175,446.679869524697,5.9994586295659,,2.15350156179006E-8,1.19311616331879E-5,1.46378019054907E-5,1.888432849062E-5,50.8167836318494,1.47629626425157E-8,-1.16876372707033E-10,1.47634252824611E-8,-0.453593438045857,200,25,5,13.4965986394558,0.621359593016433,0.000217831283917402,4369,0,11.0021667,11.007165,2499.175,2499.175,,10.9960375,,,,,,,,,,,,,,,,,,,,,,,11.0033588125
,9486379.35,11.005253075,2499.175,1778.29962721342,6.00055142792286,,2.61286219668994E-8,4.22220983106572E-6,5.41922448063264E-6,6.86986534286052E-6,52.0772381496501,1.47502262235429E-8,-5.75888628823648E-10,1.47614640655492E-8,-2.23584622378712,66,25,5,13.4965986394558,0.621359593016433,0.000587337659849042,4369,0,11.0032263,11.0098963,2499.175,2499.175,,10.9948,,,,,,,,,,,,,,,,,,,,,,,11.005253075
,9486479.69,11.01137615,2499.175,7079.5,5.9991915094299,,3.62109182335351E-8,3.05746603991559E-6,1.57775990809529E-6,3.44055590171559E-6,27.2953239254726,1.4610022466937E-8,-2.3070088859069E-9,1.47910461592159E-8,-8.97325119056325,15,5,5,13.4965986394558,0.621359593016433,0.00167157497196818,4369,0,11.0068626,11.0179415,2499.175,2499.175,,10.9900625,,,,,,,,,,,,,,,,,,,,,,,11.01137615
,9487041.10,12.0068920875,2499.175,19.952935694315,6.00079223420573,,4.30145122766689E-7,4.52999557352229E-5,9.09342392284487E-6,4.6203639989223E-5,11.350586376768,1.47494952555513E-8,4.97690786397344E-11,1.47495792229717E-8,0.193331858787189,3200,25,5,13.4965986394558,0.621359593016433,8.43219321996873E-5,4369,0,12.0012388,12.0200272,2499.175,2499.175,,11.9873875,,,,,,,,,,,,,,,,,,,,,,,12.0068920875
,9487257.95,12.006986125,2499.175,79.4333643988816,6.0007526303336,,9.16551579858005E-8,3.7884825304431E-5,1.37394275099631E-5,4.02992786120147E-5,19.9338389015294,1.47584222428676E-8,7.37479687644221E-11,1.47586065013491E-8,0.286305142847283,800,25,5,13.4965986394558,0.621359593016433,9.95970819947046E-5,4369,0,12.0000076,12.0210199,2499.175,2499.175,,11.9823,,,,,,,,,,,,,,,,,,,,,,,12.006986125
,9487383.95,12.00947285,2499.175,316.22972972973,6.00012505209523,,2.71898474570357E-8,2.00284761871888E-5,1.72755600417135E-5,2.64496660307013E-5,40.7794090616726,1.47583070021909E-8,-7.83913629684275E-11,1.47585151955305E-8,-0.304333824166861,200,25,5,13.4965986394558,0.621359593016433,0.000177731449316067,4369,0,12.0060339,12.021245,2499.175,2499.175,,11.9834125,,,,,,,,,,,,,,,,,,,,,,,12.00947285
,9487490.46,12.0067305625,2499.175,1258.90027958993,5.99855311901706,,3.57878440322059E-8,6.28249892583012E-6,8.94365640017253E-6,1.0929720150004E-5,54.913759106559,1.47525882672016E-8,-4.02966782321219E-10,1.47580907575889E-8,-1.56464451773644,66,25,5,13.4965986394558,0.621359593016433,0.000454480346023703,4369,0,12.0022249,12.0218754,2499.175,2499.175,,11.980825,,,,,,,,,,,,,,,,,,,,,,,12.0067305625
,9487591.45,12.0122460125,2499.175,5011.89934762349,6.00179066931923,,2.07150985327233E-8,3.24547349033283E-6,2.75738703829175E-6,4.2586713251192E-6,40.3515645860684,1.46819848044297E-8,-1.64196312759686E-9,1.47735141625103E-8,-6.38117139875902,18,25,5,13.4965986394558,0.621359593016433,0.00127381312816088,4369,0,12.0061083,12.027463,2499.175,2499.175,,11.9790125,,,,,,,,,,,,,,,,,,,,,,,12.0122460125
,9488089.02,13.0067688125,2499.175,14.1251164958061,6.000793564728,,3.09887055961754E-7,4.56610299869999E-5,9.73147126385105E-6,4.6686520457546E-5,12.0311147253615,1.47622173949131E-8,5.96241791572772E-11,1.47623378046099E-8,0.231414776985831,6400,25,5,13.4965986394558,0.621359593016433,8.29293451436521E-5,4369,0,13.0011663,13.0237198,2499.175,2499.175,,12.9873875,,,,,,,,,,,,,,,,,,,,,,,13.0067688125
,9488354.08,13.0066433,2499.175,56.2339235787512,6.00077371602089,,1.33913077320167E-7,3.94679737193654E-5,9.75057470632772E-6,4.06545773144451E-5,13.8770694772329,1.47528975512975E-8,5.7377990035555E-11,1.47530091301002E-8,0.222837586893472,1600,25,5,13.4965986394558,0.621359593016433,9.27459450533973E-5,4369,0,12.9991837,13.0262213,2499.175,2499.175,,12.9825875,,,,,,,,,,,,,,,,,,,,,,,13.0066433
,9488494.76,13.010337125,2499.175,223.869990680336,6.0004591650216,,6.5480530970992E-8,2.79812707217779E-5,1.60040855328111E-5,3.22347989748184E-5,29.7677029879409,1.47529841241531E-8,-5.20243531887857E-11,1.47530758522025E-8,-0.202044785589408,400,25,5,13.4965986394558,0.621359593016433,0.000147414049565397,4369,0,13.0043173,13.0316029,2499.175,2499.175,,12.9832875,,,,,,,,,,,,,,,,,,,,,,,13.010337125
,9488604.70,13.007450925,2499.175,891.250232991612,5.99965815630419,,2.66718574936672E-8,1.04157424708433E-5,1.25812195801031E-5,1.6333241482991E-5,50.379316130895,1.47726378462809E-8,-2.4864426232682E-10,1.47747302143409E-8,-0.964277463768099,66,25,5,13.4965986394558,0.621359593016433,0.000349966081353188,4369,0,13.0016212,13.0261078,2499.175,2499.175,,12.9819625,,,,,,,,,,,,,,,,,,,,,,,13.007450925
,9488705.89,13.0113996375,2499.175,3548.09972041007,6.00061147554465,,1.81244086985909E-8,3.77401986196094E-6,4.68485227617303E-6,6.01590116009557E-6,51.1458017616888,1.47168941907926E-8,-1.16029121154511E-9,1.47625624577366E-8,-4.50791837263358,28,25,5,13.4965986394558,0.621359593016433,0.000983018802512727,4369,0,13.0027905,13.0368195,2499.175,2499.175,,12.9805125,,,,,,,,,,,,,,,,,,,,,,,13.0113996375
,9489112.21,14.0121101,2499.175,10,6.00079423145365,,3.69003180765181E-7,4.80833062808271E-5,8.38708085428924E-6,4.88092969438427E-5,9.89444991987978,1.47627613829017E-8,1.20847002282278E-10,1.47632559974572E-8,0.469009040091175,6400,25,5,13.4965986394558,0.621359593016433,8.37285749470913E-5,4369,0,14.0079727,14.0378447,2499.175,2499.175,,13.9857125,,,,,,,,,,,,,,,,,,,,,,,14.0121101
,9489444.32,14.00809875,2499.175,39.8108108108108,6.00078428340379,,1.5793557198586E-7,3.92819939185305E-5,8.36852606198397E-6,4.01635067525929E-5,12.0263456481713,1.47322815977943E-8,5.00681662883853E-11,1.47323666767422E-8,0.194720929871496,1600,25,5,13.4965986394558,0.621359593016433,8.89008521131445E-5,4369,0,14.0005322,14.0377579,2499.175,2499.175,,13.9761125,,,,,,,,,,,,,,,,,,,,,,,14.00809875
,9489603.51,14.01139605,2499.175,158.490214352283,6.00062662274035,,3.90080945010383E-8,3.25145994728335E-5,1.22184971213678E-5,3.47345771643136E-5,20.5954645588643,1.47523075926887E-8,-3.11404437230387E-11,1.47523404596198E-8,-0.120944695345486,400,25,5,13.4965986394558,0.621359593016433,0.000125658766498804,4369,0,14.0044298,14.0320492,2499.175,2499.175,,13.9758875,,,,,,,,,,,,,,,,,,,,,,,14.01139605
,9489717.33,14.0108405375,2499.175,630.960391425909,5.99812947141829,,3.40430895608799E-8,1.65918438283859E-5,1.47177936633655E-5,2.2178880313103E-5,41.5746262559629,1.47635156578533E-8,-1.713037465237E-10,1.47645094586056E-8,-0.664783475527315,66,25,5,13.4965986394558,0.621359593016433,0.0002757740964617,4369,0,14.0010157,14.0470877,2499.175,2499.175,,13.9756625,,,,,,,,,,,,,,,,,,,,,,,14.0108405375
,9489819.54,14.0101511375,2499.175,2511.90074557316,6.00047446050539,,9.71312163089837E-9,5.23207116756941E-6,7.37050884017411E-6,9.03874821341959E-6,54.6303656693858,1.47362703413425E-8,-8.18199091579816E-10,1.47589672174781E-8,-3.17795952622862,40,25,5,13.4965986394558,0.621359593016433,0.000764732717728372,4369,0,14.0000181,14.0434294,2499.175,2499.175,,13.973075,,,,,,,,,,,,,,,,,,,,,,,14.0101511375
,9489921.30,14.0163758875,2499.175,10000,6.00062078406639,,3.35944570636081E-8,2.94396653987089E-6,2.2564681681566E-6,3.70925701209601E-6,37.4691572749511,1.4499461450673E-8,-3.25946562124613E-9,1.4861308774655E-8,-12.6694259589565,11,5,5,13.4965986394558,0.621359593016433,0.00214083538793804,4369,0,14.0036383,14.0503273,2499.175,2499.175,,13.97005,,,,,,,,,,,,,,,,,,,,,,,14.0163758875
,9490590.57,16.0100147875,2499.175,28.1840633737185,7.99965886133642,,3.41224860007249E-7,5.12187248335653E-5,1.06631750955503E-5,5.23169291596406E-5,11.7603630004754,1.47315572291183E-8,4.3649543046256E-11,1.4731621895684E-8,0.169766660544542,3200,25,5,13.4965986394558,0.621359593016433,9.02397053908139E-5,4369,0,16.0036507,16.0433903,2499.175,2499.175,,15.9758,,,,,,,,,,,,,,,,,,,,,,,16.0100147875
,9490772.35,16.01322245,2499.175,112.199906803355,7.99955352598623,,4.82943788872941E-8,4.37798506712801E-5,1.03003964699872E-5,4.49752542209436E-5,13.23959622731,1.47519326639681E-8,-1.55965073816744E-11,1.47519409086836E-8,-0.0605760435269644,800,25,5,13.4965986394558,0.621359593016433,0.000122042723813794,4369,0,16.0054626,16.04459,2499.175,2499.175,,15.9751125,,,,,,,,,,,,,,,,,,,,,,,16.01322245
,9490891.43,16.013592225,2499.175,446.679869524697,8.00206537769277,,3.5355540979731E-8,3.24568783847988E-5,1.67629134889166E-5,3.65300454848132E-5,27.3148705100966,1.4757490507059E-8,-1.16974381917071E-10,1.47579540950622E-8,-0.454142120937263,200,25,5,13.4965986394558,0.621359593016433,0.00027021129186705,4369,0,16.0046253,16.0504513,2499.175,2499.175,,15.97605,,,,,,,,,,,,,,,,,,,,,,,16.013592225
,9490993.83,16.0110611875,2499.175,1778.29962721342,8.00073523723047,,1.44542306422809E-8,1.31589441251269E-5,1.45976819309162E-5,1.96532472697111E-5,47.9672156873328,1.47457855194259E-8,-5.7492576306324E-10,1.47569891989506E-8,-2.23278327289631,66,25,5,13.4965986394558,0.621359593016433,0.000770321225101854,4369,0,16.0003738,16.0463886,2499.175,2499.175,,15.971225,,,,,,,,,,,,,,,,,,,,,,,16.0110611875
,9491094.02,16.0162830375,2499.175,7079.5,8.00156541046235,,1.15515469817328E-7,4.47502788467561E-6,5.91864100288432E-6,7.41998557206466E-6,52.9074222709204,1.46038671961562E-8,-2.29995652393439E-9,1.47838674606801E-8,-8.94997460246014,15,5,5,13.4965986394558,0.621359593016433,0.00222471743710361,4369,0,16.0026455,16.0534382,2499.175,2499.175,,15.9645375,,,,,,,,,,,,,,,,,,,,,,,16.0162830375
,9491716.89,18.0102608125,2499.175,19.952935694315,7.99957010636774,,2.26643074807205E-7,5.27541914034786E-5,8.57376277380182E-6,5.34463667496331E-5,9.23116307520789,1.47405302400243E-8,4.68556584060474E-11,1.47406047097734E-8,0.182125228019631,3200,25,5,13.4965986394558,0.621359593016433,8.78962710567119E-5,4369,0,18.002594,18.042366,2499.175,2499.175,,17.980325,,,,,,,,,,,,,,,,,,,,,,,18.0102608125
,9491932.57,18.013573175,2499.175,79.4333643988816,7.99951728466941,,1.13373202021585E-7,4.2289375111652E-5,8.98947742248079E-6,4.32342682563647E-5,12.000769022908,1.47603087567814E-8,7.56693121627206E-11,1.4760502716382E-8,0.293726528104403,800,25,5,13.4965986394558,0.621359593016433,0.000108366113825325,4369,0,18.005291,18.0445423,2499.175,2499.175,,17.9776375,,,,,,,,,,,,,,,,,,,,,,,18.013573175
,9492060.34,18.0118963625,2499.175,316.22972972973,7.99868217602703,,3.22341944666905E-8,3.64774268489285E-5,1.10966067184639E-5,3.81279077603687E-5,16.9200103584256,1.47551005520866E-8,-7.78421887894775E-11,1.47553058832591E-8,-0.302267510366619,200,25,5,13.4965986394558,0.621359593016433,0.000213935504786214,4369,0,17.9991398,18.0572414,2499.175,2499.175,,17.9785875,,,,,,,,,,,,,,,,,,,,,,,18.0118963625
,9492164.99,18.0091648,2499.175,1258.90027958993,7.99797976193057,,2.73825651340548E-8,2.19052304751167E-5,1.57286278141574E-5,2.6967181074118E-5,35.6795073870705,1.47495402401531E-8,-4.01983684773923E-10,1.47550170511158E-8,-1.56115161409082,66,25,5,13.4965986394558,0.621359593016433,0.000592933166466383,4369,0,17.9987621,18.0478191,2499.175,2499.175,,17.9738875,,,,,,,,,,,,,,,,,,,,,,,18.0091648
,9492265.18,18.012300725,2499.175,5011.89934762349,7.99958794448357,,2.7477933869002E-8,7.73994182092266E-6,9.6394290842484E-6,1.23622527260011E-5,51.23741389238,1.46703931054836E-8,-1.62790224165304E-9,1.47604369710995E-8,-6.3319301442591,18,5,5,13.4965986394558,0.621359593016433,0.00171948090770525,4369,0,18.0033627,18.0423164,2499.175,2499.175,,17.9677875,,,,,,,,,,,,,,,,,,,,,,,18.012300725
,9492825.19,20.0106999875,2499.175,14.1251164958061,7.99922013605086,,3.06623438798576E-7,5.06410889918405E-5,4.88636764051524E-6,5.08762860574334E-5,5.51141774990301,1.47413043912628E-8,6.00107847551904E-11,1.47414265405404E-8,0.233245688890462,6400,25,5,13.4965986394558,0.621359593016433,8.67212657032236E-5,4369,0,20.0004349,20.0423546,2499.175,2499.175,,19.981425,,,,,,,,,,,,,,,,,,,,,,,20.0106999875
,9493090.79,20.010931725,2499.175,56.2339235787512,7.99919467690622,,9.63481553643354E-8,4.26438516023682E-5,8.53834010524028E-6,4.34902440926417E-5,11.3222952582974,1.47480465938975E-8,6.00552181434052E-11,1.47481688682019E-8,0.23331167939905,1600,25,5,13.4965986394558,0.621359593016433,9.92299279090948E-5,4369,0,20.0038776,20.0341473,2499.175,2499.175,,19.97885,,,,,,,,,,,,,,,,,,,,,,,20.010931725
,9493233.60,20.0130779875,2499.175,223.869990680336,7.99877764794414,,5.73107094672432E-8,3.59757746844296E-5,7.71276007446944E-6,3.6793247099314E-5,12.100338420545,1.47522715343458E-8,-5.13317888989483E-11,1.47523608407475E-8,-0.1993647542497,400,25,5,13.4965986394558,0.621359593016433,0.000172175216233706,4369,0,20.0015507,20.0521851,2499.175,2499.175,,19.981475,,,,,,,,,,,,,,,,,,,,,,,20.0130779875
,9493341.66,20.0085222625,2499.175,891.250232991612,8.00049521614282,,1.5116860216804E-8,2.87306780683838E-5,1.2247285116487E-5,3.12321605879842E-5,23.0875340172485,1.47708708412051E-8,-2.47881178772581E-10,1.47729506357515E-8,-0.961433653236213,66,25,5,13.4965986394558,0.621359593016433,0.000450090264737409,4369,0,19.9994011,20.0401058,2499.175,2499.175,,19.9732375,,,,,,,,,,,,,,,,,,,,,,,20.0085222625
,9493444.97,20.011487,2499.175,3548.09972041007,8.00038468077457,,4.13074117161174E-8,1.36437866259724E-5,1.26410366296892E-5,1.85996967869965E-5,42.8152603737871,1.47136775062518E-8,-1.15932117696606E-9,1.47592794996688E-8,-4.50514578760607,28,25,5,13.4965986394558,0.621359593016433,0.00132912391208553,4369,0,20.0020561,20.0411968,2499.175,2499.175,,19.9688125,,,,,,,,,,,,,,,,,,,,,,,20.011487
,9493954.20,22.0094149,2499.175,10,7.99859632558737,,4.29978692660567E-7,4.78059888114922E-5,3.16287507257748E-6,4.79105034931721E-5,3.78520927003397,1.47355085599526E-8,1.23489490786328E-10,1.4736025996678E-8,0.480150445845438,6400,25,5,13.4965986394558,0.621359593016433,8.68470588843679E-5,4369,0,22.0027828,22.0296974,2499.175,2499.175,,21.9955,,,,,,,,,,,,,,,,,,,,,,,22.0094149
,9494287.32,22.014249325,2499.175,39.8108108108108,7.99857881691949,,2.18853107797251E-7,4.30432775944516E-5,6.48450957839715E-6,4.35289858662633E-5,8.56723669155971,1.47484185180287E-8,4.88896969868202E-11,1.47484995503069E-8,0.189929722654931,1600,25,5,13.4965986394558,0.621359593016433,9.39155770290491E-5,4369,0,22.0020752,22.039257,2499.175,2499.175,,21.974825,,,,,,,,,,,,,,,,,,,,,,,22.014249325
,9494445.93,22.015255675,2499.175,158.490214352283,7.99837659113287,,5.20297472965407E-8,3.54758528892259E-5,7.0877128418177E-6,3.61769513854618E-5,11.298350542133,1.47502436206185E-8,-3.05375778803745E-11,1.47502752317121E-8,-0.118619859732348,400,25,5,13.4965986394558,0.621359593016433,0.000142168349602189,4369,0,22.0024738,22.0506859,2499.175,2499.175,,21.9787375,,,,,,,,,,,,,,,,,,,,,,,22.015255675
,9494561.53,22.0106530125,2499.175,630.960391425909,7.99922597078039,,3.08566179975901E-8,3.09978969829968E-5,7.77460671500677E-6,3.19580056784135E-5,14.0799567782081,1.47613438383564E-8,-1.70273244705207E-10,1.47623258632251E-8,-0.660881944425739,66,25,5,13.4965986394558,0.621359593016433,0.000347181937685352,4369,0,22.0017567,22.0456924,2499.175,2499.175,,21.9718375,,,,,,,,,,,,,,,,,,,,,,,22.0106530125
,9494664.27,22.0096061375,2499.175,2511.90074557316,8.00096184075899,,1.7683847144129E-8,2.10477896153119E-5,1.22429415542128E-5,2.43495187958674E-5,30.1854295907536,1.473464113914E-8,-8.17029115818716E-10,1.4757275699645E-8,-3.1737746955132,40,25,5,13.4965986394558,0.621359593016433,0.00103680207553151,4369,0,21.9993134,22.0384159,2499.175,2499.175,,21.965975,,,,,,,,,,,,,,,,,,,,,,,22.0096061375
,9494764.39,22.0172576875,2499.175,10000,7.9986916970204,,5.52729700217098E-8,8.78683150856672E-6,9.04743151955933E-6,1.26120745740364E-5,45.8371648536631,1.45049030648894E-8,-3.24996347218577E-9,1.48645375135717E-8,-12.6290911182755,11,5,5,13.4965986394558,0.621359593016433,0.00294049899867884,4369,0,22.0066776,22.0531864,2499.175,2499.175,,21.9613375,,,,,,,,,,,,,,,,,,,,,,,22.0172576875
,9495474.18,24.0151932375,2499.175,28.1840633737185,8.0018423760436,,2.93689062875083E-7,4.18916567844033E-5,4.21090242759343E-6,4.21027624675264E-5,5.74002691253793,1.47277452333848E-8,4.41753012125525E-11,1.4727811484288E-8,0.171855955387793,3200,25,5,13.4965986394558,0.621359593016433,9.1064799587571E-5,4369,0,24.0063782,24.051796,2499.175,2499.175,,23.9768125,,,,,,,,,,,,,,,,,,,,,,,24.0151932375
,9495657.84,24.020566,2499.175,112.199906803355,8.00174139647667,,6.72855325290834E-8,3.58636384175871E-5,6.97256870880739E-6,3.65351512238074E-5,11.002129926329,1.47513683477952E-8,-1.51320824036805E-11,1.47513761091043E-8,-0.0587744900962548,800,25,5,13.4965986394558,0.621359593016433,0.000121555751422396,4369,0,24.0117226,24.0543346,2499.175,2499.175,,23.9787875,,,,,,,,,,,,,,,,,,,,,,,24.020566
,9495776.33,24.01218675,2499.175,446.679869524697,8.00006954406287,,3.87790374519726E-8,3.05125104228343E-5,5.60345128577402E-6,3.10227651671416E-5,10.4060994099104,1.47566124504737E-8,-1.16226186744446E-10,1.47570701543349E-8,-0.451264292188228,200,25,5,13.4965986394558,0.621359593016433,0.000270102220316935,4369,0,24.0029964,24.0441723,2499.175,2499.175,,23.9618875,,,,,,,,,,,,,,,,,,,,,,,24.01218675
,9495881.62,24.012572525,2499.175,1778.29962721342,7.9987546415074,,1.87229691629019E-8,2.59200768098895E-5,8.72926035088643E-6,2.7350509466994E-5,18.6122914589795,1.4746187874488E-8,-5.72328375794152E-10,1.47572902864799E-8,-2.22264560635563,66,25,5,13.4965986394558,0.621359593016433,0.000798341531345464,4369,0,24.0010967,24.0503712,2499.175,2499.175,,23.9615375,,,,,,,,,,,,,,,,,,,,,,,24.012572525
,9495981.64,24.0152966875,2499.175,7079.5,7.99976844658288,,3.37500707883446E-8,1.45000271697858E-5,1.07732683080635E-5,1.8064166129718E-5,36.6117076440309,1.46072758900831E-8,-2.28373365398997E-9,1.47847200964837E-8,-8.88581587147638,15,5,5,13.4965986394558,0.621359593016433,0.00234405454487719,4369,0,24.0050488,24.0469341,2499.175,2499.175,,23.9568,,,,,,,,,,,,,,,,,,,,,,,24.0152966875
,9496660.98,26.013607,2499.175,19.952935694315,8.00060331437745,,1.92590834886682E-7,4.03943638465311E-5,2.82045824638431E-6,4.04927106438373E-5,3.99408455481014,1.47407488762856E-8,4.9918920813037E-11,1.47408334001972E-8,0.194028985301121,3200,25,5,13.4965986394558,0.621359593016433,8.89021353078518E-5,4369,0,26.0062885,26.0462379,2499.175,2499.175,,25.984975,,,,,,,,,,,,,,,,,,,,,,,26.013607
,9496879.51,26.0204179125,2499.175,79.4333643988816,8.00055055441568,,4.98551939998468E-8,3.63291881409065E-5,5.63277178196203E-6,3.67632701065213E-5,8.81342452236407,1.47610697851239E-8,7.54574318828932E-11,1.47612626501029E-8,0.292888983254727,800,25,5,13.4965986394558,0.621359593016433,0.000108333071561613,4369,0,26.0100498,26.0622005,2499.175,2499.175,,25.978675,,,,,,,,,,,,,,,,,,,,,,,26.0204179125
,9497006.69,26.013266575,2499.175,316.22972972973,7.99971278786998,,3.38738352340368E-8,2.98867035968414E-5,5.44851796504225E-6,3.0379292287689E-5,10.3318859005744,1.47558045221749E-8,-7.69764639537674E-11,1.47560053019996E-8,-0.298891632250616,200,25,5,13.4965986394558,0.621359593016433,0.000212558636865342,4369,0,26.0006924,26.0505257,2499.175,2499.175,,25.9676,,,,,,,,,,,,,,,,,,,,,,,26.013266575
,9497113.75,26.0153570125,2499.175,1258.90027958993,7.99901586165002,,2.60077786044976E-8,2.72916367496005E-5,5.42344550211331E-6,2.78252977987036E-5,11.2395011692473,1.47507566978982E-8,-3.99494895803855E-10,1.47561654684529E-8,-1.55136295893658,66,25,5,13.4965986394558,0.621359593016433,0.000605205174030195,4369,0,26.0026627,26.0597458,2499.175,2499.175,,25.9647875,,,,,,,,,,,,,,,,,,,,,,,26.0153570125
,9497214.36,26.018777825,2499.175,5011.89934762349,8.00067418102889,,3.3358911129205E-8,2.05110453465283E-5,9.30002995116401E-6,2.25209577571623E-5,24.3902856453934,1.46690684764873E-8,-1.62064231575371E-9,1.47583214317715E-8,-6.30448425797761,18,5,5,13.4965986394558,0.621359593016433,0.00183703580060765,4369,0,26.0044174,26.0569324,2499.175,2499.175,,25.9608625,,,,,,,,,,,,,,,,,,,,,,,26.018777825
,9497839.57,28.019228225,2499.175,14.1251164958061,7.99900747519355,,2.73396294056246E-7,3.79876815130531E-5,1.19205617510023E-6,3.80063803151754E-5,1.79735587491819,1.47389237224587E-8,6.26160338731647E-11,1.47390567291179E-8,0.243410777804449,6400,25,5,13.4965986394558,0.621359593016433,8.73680760353431E-5,4369,0,28.007061,28.064188,2499.175,2499.175,,27.9782875,,,,,,,,,,,,,,,,,,,,,,,28.019228225
,9498104.47,28.0152805,2499.175,56.2339235787512,7.99898960831788,,9.46791087496939E-8,3.59909443611658E-5,3.79534912126371E-6,3.61905063650789E-5,6.01975749992583,1.47493194442022E-8,5.96596338570811E-11,1.47494401025609E-8,0.231754868293077,1600,25,5,13.4965986394558,0.621359593016433,0.000100072666033076,4369,0,28.0043755,28.0545464,2499.175,2499.175,,27.9724,,,,,,,,,,,,,,,,,,,,,,,28.0152805
,9498248.11,28.01177095,2499.175,223.869990680336,7.99858164408364,,3.68410220500081E-8,3.01881904279694E-5,5.67996623749131E-6,3.07178914929782E-5,10.6557351611282,1.47538589024031E-8,-5.05810278428643E-11,1.47539456062572E-8,-0.196427801293964,400,25,5,13.4965986394558,0.621359593016433,0.000170446111365697,4369,0,27.9982185,28.0565357,2499.175,2499.175,,27.9746875,,,,,,,,,,,,,,,,,,,,,,,28.01177095
,9498357.40,28.0110463875,2499.175,891.250232991612,8.00030052943162,,2.26144700560583E-8,2.63523260552151E-5,3.99475642343409E-6,2.66533894167879E-5,8.61985594971462,1.47729316785959E-8,-2.45487439476459E-10,1.47749712170076E-8,-0.952018195550295,66,25,5,13.4965986394558,0.621359593016433,0.000453706540730547,4369,0,27.9987659,28.047699,2499.175,2499.175,,27.968325,,,,,,,,,,,,,,,,,,,,,,,28.0110463875
,9498461.27,28.0126299625,2499.175,3548.09972041007,8.00024449082526,,3.73520460706652E-8,2.3508952489696E-5,6.09337166895614E-6,2.42857988433327E-5,14.5309337115602,1.4716137936559E-8,-1.15595966607518E-9,1.47614687113926E-8,-4.4913884514695,28,25,5,13.4965986394558,0.621359593016433,0.00142524436133449,4369,0,27.9991264,28.0545921,2499.175,2499.175,,27.9614125,,,,,,,,,,,,,,,,,,,,,,,28.0126299625
,9498997.62,30.0239830125,2499.175,10,8.00122826816376,,7.65138954002243E-7,3.52863749713868E-5,2.32224617154202E-7,3.5287139114614E-5,0.377066173120075,1.47362683235101E-8,1.29913173633022E-10,1.47368409618605E-8,0.505099633291604,6400,25,5,13.4965986394558,0.621359593016433,8.69265768563824E-5,4369,0,30.0090408,30.0736866,2499.175,2499.175,,29.9821875,,,,,,,,,,,,,,,,,,,,,,,30.0239830125
,9499330.42,30.0178525375,2499.175,39.8108108108108,8.00122829512657,,1.65737832876067E-7,3.43890135934575E-5,2.40201663815267E-6,3.44728000003041E-5,3.99552760662178,1.47498298411184E-8,5.03209419603651E-11,1.47499156790521E-8,0.195471164116247,1600,25,5,13.4965986394558,0.621359593016433,9.54655158360599E-5,4369,0,30.0083141,30.0560265,2499.175,2499.175,,29.96895,,,,,,,,,,,,,,,,,,,,,,,30.0178525375
,9499489.94,30.012515525,2499.175,158.490214352283,8.0010306485604,,5.24776283129905E-8,3.1166396230565E-5,5.08215603145237E-6,3.15780392666898E-5,9.26143636462452,1.47517813953265E-8,-2.96833477923242E-11,1.47518112595246E-8,-0.115289686674885,400,25,5,13.4965986394558,0.621359593016433,0.000141676244431962,4369,0,29.9977779,30.061964,2499.175,2499.175,,29.9780875,,,,,,,,,,,,,,,,,,,,,,,30.012515525
,9499606.97,30.01315235,2499.175,630.960391425909,8.00187720942172,,2.87288972198717E-8,2.56836128626089E-5,4.04390839843345E-6,2.60000224002075E-5,8.94781446242666,1.47641292506106E-8,-1.68273235108594E-10,1.47650881612806E-8,-0.652996771450319,66,25,5,13.4965986394558,0.621359593016433,0.000347403580407513,4369,0,29.9992237,30.0569096,2499.175,2499.175,,29.96335,,,,,,,,,,,,,,,,,,,,,,,30.01315235
,9499712.64,30.0132250875,2499.175,2511.90074557316,7.99948236664765,,2.7821770502513E-8,2.38222442347608E-5,3.72270581588698E-6,2.41113636896015E-5,8.88178646174132,1.4739133592341E-8,-8.13493754482529E-10,1.47615660125021E-8,-3.15910813891065,40,25,5,13.4965986394558,0.621359593016433,0.00108970819331113,4369,0,29.9985752,30.0566883,2499.175,2499.175,,29.960425,,,,,,,,,,,,,,,,,,,,,,,30.0132250875
,9499814.50,30.0180938375,2499.175,10000,8.00156910100685,,4.15418807194116E-8,1.96999208935938E-5,6.901900467917E-6,2.08739817304434E-5,19.3079952817375,1.45090312592023E-8,-3.22680215011952E-9,1.48635204509741E-8,-12.5384898332339,11,5,5,13.4965986394558,0.621359593016433,0.00320110417831341,4369,0,30.0051403,30.0558891,2499.175,2499.175,,29.950725,,,,,,,,,,,,,,,,,,,,,,,30.0180938375
,9500916.84,35.0133728875,2499.175,28.1840633737185,9.99845575741538,,1.4146854751638E-7,3.85963592339155E-5,1.64641360970002E-6,3.863145899248E-5,2.44259817162284,1.47470182219513E-8,4.81039568382402E-11,1.47470966779644E-8,0.186894997203721,3200,25,5,13.4965986394558,0.621359593016433,9.77804792875949E-5,4369,0,34.9992599,35.0473557,2499.175,2499.175,,34.95745,,,,,,,,,,,,,,,,,,,,,,,35.0133728875
,9501100.84,35.014069575,2499.175,112.199906803355,9.99836668176491,,1.77813965413922E-7,3.70086519525009E-5,3.81426081533388E-6,3.72046892865502E-5,5.88435769933902,1.47550325767722E-8,-1.37705773418822E-11,1.47550390026733E-8,-0.0534729916703327,800,25,5,13.4965986394558,0.621359593016433,0.00013434471147213,4369,0,34.9995079,35.0583878,2499.175,2499.175,,34.9711375,,,,,,,,,,,,,,,,,,,,,,,35.014069575
,9501222.11,35.012270475,2499.175,446.679869524697,10.000442173352,,3.96853462519332E-8,3.1149369521008E-5,5.58859767599119E-6,3.16467319883175E-5,10.1713858576083,1.47599457297674E-8,-1.13821291751741E-10,1.4760384589574E-8,-0.441827530312764,200,25,5,13.4965986394558,0.621359593016433,0.00031578651828419,4369,0,35.0003357,35.0501442,2499.175,2499.175,,34.9576875,,,,,,,,,,,,,,,,,,,,,,,35.012270475
,9501326.89,35.0120907,2499.175,1778.29962721342,10.000918038715,,2.14282252021638E-8,2.69951121134864E-5,3.16683788442895E-6,2.71802306871365E-5,6.69087409145556,1.47532355108818E-8,-5.68733885785282E-10,1.47641937223942E-8,-2.20764616644311,66,25,5,13.4965986394558,0.621359593016433,0.00101349051059316,4369,0,35.000309,35.0461998,2499.175,2499.175,,34.949575,,,,,,,,,,,,,,,,,,,,,,,35.0120907
,9501444.61,35.017803675,2499.175,7079.5,10.0007118997814,,1.74402611214886E-7,2.56863056705518E-5,3.95157592703988E-6,2.59884830513091E-5,8.74580619502656,1.46105870684397E-8,-2.28622277584933E-9,1.47883761470037E-8,-8.89336232539739,15,5,5,13.4965986394558,0.621359593016433,0.00326881019723011,4369,0,35.0051918,35.0520935,2499.175,2499.175,,34.9376375,,,,,,,,,,,,,,,,,,,,,,,35.017803675
,9502481.79,40.0123848625,2499.175,19.952935694315,9.99924777232464,,3.47544406342914E-7,3.34591688743669E-5,3.18964265488234E-7,3.34606891735071E-5,0.546180711343398,1.47356838820523E-8,5.78626953744993E-11,1.47357974865052E-8,0.224982513428419,3200,25,5,13.4965986394558,0.621359593016433,9.48588053385417E-5,4369,0,40.0015144,40.0509567,2499.175,2499.175,,39.95755,,,,,,,,,,,,,,,,,,,,,,,40.0123848625
,9502703.26,40.018007275,2499.175,79.4333643988816,9.99921332061587,,4.84590305864533E-8,3.37072330023124E-5,1.80975803678835E-6,3.37557814429454E-5,3.07328795926324,1.47633083476524E-8,7.99892828105357E-11,1.47635250415755E-8,0.310432008707104,800,25,5,13.4965986394558,0.621359593016433,0.000119572253203675,4369,0,40.0062752,40.0595665,2499.175,2499.175,,39.963575,,,,,,,,,,,,,,,,,,,,,,,40.018007275
,9502834.55,40.01318025,2499.175,316.22972972973,9.99815930485007,,3.02089363483223E-8,3.08507583011486E-5,4.31646894349536E-6,3.1151263086688E-5,7.96480666863021,1.47611318346313E-8,-7.49198980438812E-11,1.47613219608031E-8,-0.290801352380811,200,25,5,13.4965986394558,0.621359593016433,0.000241837290500499,4369,0,40.0022011,40.0488319,2499.175,2499.175,,39.9479375,,,,,,,,,,,,,,,,,,,,,,,40.01318025
,9502943.58,40.012993325,2499.175,1258.90027958993,9.99837156972698,,4.07937914953145E-8,2.53274563259659E-5,4.04247128353171E-6,2.56480334143163E-5,9.06839089485348,1.47584470499196E-8,-3.94938292176925E-10,1.47637304086707E-8,-1.53287796032612,66,25,5,13.4965986394558,0.621359593016433,0.000751897659880897,4369,0,40.0007095,40.0458641,2499.175,2499.175,,39.94225,,,,,,,,,,,,,,,,,,,,,,,40.012993325
,9503068.58,40.0149474,2499.175,5011.89934762349,9.99900322397295,,3.58730483643328E-8,2.34615842560929E-5,1.86888174615689E-6,2.35359014016218E-5,4.55439890367403,1.46779632590348E-8,-1.6261984959601E-9,1.47677732573952E-8,-6.32212107501243,18,5,5,13.4965986394558,0.621359593016433,0.0025751579116516,4369,0,40.0023117,40.0496826,2499.175,2499.175,,39.942875,,,,,,,,,,,,,,,,,,,,,,,40.0149474
,9504089.43,45.0138812125,2499.175,14.1251164958061,10.000488362177,,5.55526632491176E-7,2.94767480638093E-5,3.73965000750806E-7,2.94791201741007E-5,0.726859921049111,1.4717567980177E-8,5.64777543686315E-11,1.47176763447179E-8,0.219867921258271,6400,25,5,13.4965986394558,0.621359593016433,8.79070579122196E-5,4369,0,45.0052605,45.0474777,2499.175,2499.175,,44.945425,,,,,,,,,,,,,,,,,,,,,,,45.0138812125
,9504356.79,45.0170593375,2499.175,56.2339235787512,10.0004649514369,,1.00755900716133E-7,3.04772214859939E-5,9.58086567949323E-7,3.04922770448193E-5,1.80056586602407,1.47581033632842E-8,6.98920288576054E-11,1.47582688611191E-8,0.271341664910841,1600,25,5,13.4965986394558,0.621359593016433,0.000112420046704181,4369,0,45.0087242,45.0538101,2499.175,2499.175,,44.941975,,,,,,,,,,,,,,,,,,,,,,,45.0170593375
,9504500.29,45.0165243125,2499.175,223.869990680336,9.999933204397,,4.99521842904428E-8,2.95839251430097E-5,2.40155936262819E-6,2.96812417907241E-5,4.64097147826583,1.47597678682251E-8,-4.77291927805771E-11,1.47598450398279E-8,-0.185278779323369,400,25,5,13.4965986394558,0.621359593016433,0.000192960404101624,4369,0,45.0041809,45.0480232,2499.175,2499.175,,44.927875,,,,,,,,,,,,,,,,,,,,,,,45.0165243125
,9504610.25,45.0145154125,2499.175,891.250232991612,10.0000220621069,,2.0342664516527E-8,2.58216366870439E-5,4.39198836285008E-6,2.61924890565426E-5,9.65302721552803,1.47795470810809E-8,-2.4120372909894E-10,1.47815151848793E-8,-0.93499001276723,66,25,5,13.4965986394558,0.621359593016433,0.000548103009557894,4369,0,45.0011635,45.0431557,2499.175,2499.175,,44.9253,,,,,,,,,,,,,,,,,,,,,,,45.0145154125
,9504733.92,45.015208725,2499.175,3548.09972041007,9.99940355290895,,5.50541070368805E-8,2.16771304473516E-5,2.5174566378531E-6,2.18228222820736E-5,6.62432591883619,1.47253495814917E-8,-1.14844818660437E-9,1.47700661316886E-8,-4.45954125644255,28,5,5,13.4965986394558,0.621359593016433,0.001922500641744,4369,0,45.0019341,45.0433083,2499.175,2499.175,,44.919875,,,,,,,,,,,,,,,,,,,,,,,45.015208725
,9505419.23,50.035530575,2499.175,10,10.0019457077097,,2.47725788239704E-7,2.71316280147462E-5,4.87292665446986E-7,2.71360036275123E-5,1.02893979027104,1.47023407501846E-8,1.35359865076428E-10,1.4702963845008E-8,0.527489465733412,6400,25,5,13.4965986394558,0.621359593016433,8.26871822424947E-5,4369,0,50.0282059,50.0760307,2499.175,2499.175,,49.947225,,,,,,,,,,,,,,,,,,,,,,,50.035530575
,9505754.19,50.0259103875,2499.175,39.8108108108108,10.0019930152865,,1.20726580970897E-7,2.78286438733068E-5,2.09567721062308E-7,2.78294329524884E-5,0.431466190732507,1.4747601336705E-8,6.99066894268328E-11,1.47477670218785E-8,0.271591845568162,1600,25,5,13.4965986394558,0.621359593016433,0.000106688176346266,4369,0,50.0172691,50.0591431,2499.175,2499.175,,49.918675,,,,,,,,,,,,,,,,,,,,,,,50.0259103875
,9505913.45,50.012876975,2499.175,158.490214352283,10.001744687197,,4.66750214178665E-8,2.75869027778047E-5,9.90796519276637E-7,2.76046895040437E-5,2.05692060839919,1.47608829689645E-8,-2.47976263444089E-11,1.47609037984041E-8,-0.0962542686538086,400,25,5,13.4965986394558,0.621359593016433,0.000161130117791115,4369,0,50.0040016,50.0398369,2499.175,2499.175,,49.9170625,,,,,,,,,,,,,,,,,,,,,,,50.012876975
,9506030.93,50.0130300875,2499.175,630.960391425909,10.001822675349,,4.63046390945262E-8,2.63870383220842E-5,2.82797010061988E-6,2.65381462483939E-5,6.11719393607754,1.47703096924726E-8,-1.64873645695536E-10,1.47712298652006E-8,-0.639537824545982,66,25,5,13.4965986394558,0.621359593016433,0.000407589300646006,4369,0,50.0010033,50.0408173,2499.175,2499.175,,49.9229,,,,,,,,,,,,,,,,,,,,,,,50.0130300875
,9506138.62,50.01481435,2499.175,2511.90074557316,9.99917062704984,,1.26554645688705E-8,2.16351561720533E-5,3.37272789106538E-6,2.18964672040104E-5,8.86058362735288,1.4751038017722E-8,-8.10510461667367E-10,1.47732883884649E-8,-3.14501116570023,40,25,5,13.4965986394558,0.621359593016433,0.00140507895651017,4369,0,50.0022087,50.043354,2499.175,2499.175,,49.9177,,,,,,,,,,,,,,,,,,,,,,,50.01481435
,9506265.13,50.0210314,2499.175,10000,9.99947332471731,,1.18926679296038E-7,1.9495634888874E-5,1.75829581823993E-6,1.95747639552747E-5,5.15351793973355,1.44832647758208E-8,-3.26889367600033E-9,1.48475797499635E-8,-12.7186305846105,11,5,5,13.4965986394558,0.621359593016433,0.0046887934602649,4369,0,50.0056038,50.0533943,2499.175,2499.175,,49.9044,,,,,,,,,,,,,,,,,,,,,,,50.0210314
,9507376.61,55.02018165,2499.175,28.1840633737185,9.99985250347512,,1.97205481921878E-7,2.46738586889341E-5,-1.23729420455192E-8,2.46738617911989E-5,-0.0287315133349466,1.47276417958592E-8,7.17836442803737E-11,1.47278167342863E-8,0.279261767992401,3200,25,5,13.4965986394558,0.621359593016433,9.68079780988434E-5,4369,0,55.0103149,55.0516396,2499.175,2499.175,,54.8954875,,,,,,,,,,,,,,,,,,,,,,,55.02018165
,9507562.50,55.015645525,2499.175,112.199906803355,9.99969404710152,,8.5036936920008E-8,2.55468250758045E-5,2.91524824210087E-7,2.55484883736178E-5,0.653796197010285,1.47600914897399E-8,-5.16137618531971E-12,1.47600923921667E-8,-0.0200354489706456,800,25,5,13.4965986394558,0.621359593016433,0.000139977936236926,4369,0,55.0029221,55.0390701,2499.175,2499.175,,54.887775,,,,,,,,,,,,,,,,,,,,,,,55.015645525
,9507682.08,55.0172734125,2499.175,446.679869524697,10.0018471476302,,2.81242086035946E-8,2.52156054772877E-5,1.05383989148484E-6,2.52376175203426E-5,2.39317909561999,1.47656669558235E-8,-1.11274572451176E-10,1.47660862343674E-8,-0.431774785283665,200,25,5,13.4965986394558,0.621359593016433,0.000310004442933354,4369,0,55.0049171,55.0506592,2499.175,2499.175,,54.8921125,,,,,,,,,,,,,,,,,,,,,,,55.0172734125
,9507786.67,55.01204585,2499.175,1778.29962721342,9.99841617422185,,1.84070956596721E-8,2.36621187638126E-5,2.82048224674503E-6,2.38296240947476E-5,6.7974821848168,1.47631488680322E-8,-5.65551074046581E-10,1.4773977545571E-8,-2.19383092275172,66,25,5,13.4965986394558,0.621359593016433,0.00102390383006587,4369,0,55.0007973,55.0369453,2499.175,2499.175,,54.885925,,,,,,,,,,,,,,,,,,,,,,,55.01204585
,9507908.38,55.01262285,2499.175,7079.5,10.0013943236461,,1.36131971825264E-7,1.99837877811162E-5,3.2604327372893E-6,2.02480170810645E-5,9.26638380255622,1.46227201768171E-8,-2.32481450200106E-9,1.48063738922874E-8,-9.03364588936796,15,5,5,13.4965986394558,0.621359593016433,0.00359696585702898,4369,0,54.9999886,55.0390892,2499.175,2499.175,,54.8770625,,,,,,,,,,,,,,,,,,,,,,,55.01262285
,9508785.45,60.0234375,2499.175,19.952935694315,9.99835009739386,,1.69084633251343E-7,2.40307561446708E-5,1.144714271949E-7,2.40310287876378E-5,0.272928575597167,1.46948553164638E-8,6.30296550478795E-11,1.46949904902732E-8,0.24575342828214,3200,25,5,13.4965986394558,0.621359593016433,8.62954856594266E-5,4369,0,60.0126991,60.0430946,2499.175,2499.175,,59.8828375,,,,,,,,,,,,,,,,,,,,,,,60.0234375
,9509003.64,60.0115857125,2499.175,79.4333643988816,9.99840005835567,,5.54870305008132E-8,2.36497946064124E-5,1.40703031021996E-7,2.36502131548202E-5,0.340873773396134,1.47633320980644E-8,9.39919326122908E-11,1.47636312986045E-8,0.364773226735618,800,25,5,13.4965986394558,0.621359593016433,0.000126542887652095,4369,0,60.0039635,60.0328941,2499.175,2499.175,,59.9039375,,,,,,,,,,,,,,,,,,,,,,,60.0115857125
,9509135.39,60.0209345875,2499.175,316.22972972973,10.0014745150086,,3.41568072127559E-8,2.33006530751655E-5,2.71852112064575E-7,2.33022388902881E-5,0.668447872879196,1.47647714043063E-8,-7.12797804661576E-11,1.4764943461745E-8,-0.276604272807731,200,25,5,13.4965986394558,0.621359593016433,0.000243085838950646,4369,0,60.0089569,60.0467339,2499.175,2499.175,,59.8796875,,,,,,,,,,,,,,,,,,,,,,,60.0209345875
,9509243.05,60.0173297125,2499.175,1258.90027958993,10.0018298358476,,2.86101557957401E-8,2.31838858148058E-5,1.03460232200906E-6,2.32069593751241E-5,2.55518179915067,1.47633390494752E-8,-3.92645104556264E-10,1.47685595122846E-8,-1.52347684728846,66,25,5,13.4965986394558,0.621359593016433,0.000742009283697508,4369,0,60.0064507,60.0434914,2499.175,2499.175,,59.8777875,,,,,,,,,,,,,,,,,,,,,,,60.0173297125
,9509368.64,60.0121722375,2499.175,5011.89934762349,10.000334417454,,2.46360337253326E-8,2.1768379725763E-5,2.53712111574756E-6,2.19157326923145E-5,6.64787295149478,1.46998764731108E-8,-1.64417706274185E-9,1.47915410467727E-8,-6.38199141598864,18,5,5,13.4965986394558,0.621359593016433,0.00267161138047934,4369,0,60.0014267,60.035141,2499.175,2499.175,,59.878125,,,,,,,,,,,,,,,,,,,,,,,60.0121722375
,9509418.28,60.0131530625,2499.175,10000,10.000362467985,,1.22814937644737E-7,2.02252501892171E-5,3.14306534883402E-6,2.04680141929662E-5,8.83328227694312,1.44886188170221E-8,-3.30257946832177E-9,1.48602525674884E-8,-12.8407791942362,11,5,5,13.4965986394558,0.621359593016433,0.00479273223155156,4369,0,60.0028839,60.0368385,2499.175,2499.175,,59.872525,,,,,,,,,,,,,,,,,,,,,,,60.0131530625